2022-03-27 14:17:58 connectionpool.py [line:230] DEBUG:Starting new HTTP connection (1): 192.168.0.1:8885
2022-03-27 14:17:58 connectionpool.py [line:230] DEBUG:Starting new HTTP connection (1): 192.168.0.1:8885
2022-03-27 14:18:01 connectionpool.py [line:941] DEBUG:Starting new HTTPS connection (1): httpbin.org:443
2022-03-27 14:18:01 connectionpool.py [line:941] DEBUG:Starting new HTTPS connection (1): httpbin.org:443
2022-03-27 17:06:42 _internal.py [line:225] INFO: * Running on http://127.0.0.1:8888/ (Press CTRL+C to quit)
2022-03-27 17:06:46 _internal.py [line:225] INFO:127.0.0.1 - - [27/Mar/2022 17:06:46] "[33mGET / HTTP/1.1[0m" 404 -
2022-03-27 17:06:46 _internal.py [line:225] INFO:127.0.0.1 - - [27/Mar/2022 17:06:46] "[33mGET /favicon.ico HTTP/1.1[0m" 404 -
2022-03-27 17:06:49 _internal.py [line:225] INFO:127.0.0.1 - - [27/Mar/2022 17:06:49] "[33mGET / HTTP/1.1[0m" 404 -
2022-03-27 17:07:00 _internal.py [line:225] INFO:127.0.0.1 - - [27/Mar/2022 17:07:00] "[33mGET / HTTP/1.1[0m" 404 -
2022-03-27 17:07:00 _internal.py [line:225] INFO:127.0.0.1 - - [27/Mar/2022 17:07:00] "[33mGET /favicon.ico HTTP/1.1[0m" 404 -
2022-03-27 17:07:16 _internal.py [line:225] INFO:127.0.0.1 - - [27/Mar/2022 17:07:16] "[33mGET /favicon.ico HTTP/1.1[0m" 404 -
2022-03-27 17:07:16 _internal.py [line:225] INFO:127.0.0.1 - - [27/Mar/2022 17:07:16] "[33mGET /favicon.ico HTTP/1.1[0m" 404 -
2022-03-27 17:07:17 _internal.py [line:225] INFO:127.0.0.1 - - [27/Mar/2022 17:07:17] "[33mGET /favicon.ico HTTP/1.1[0m" 404 -
2022-03-27 17:07:17 app.py [line:1458] ERROR:Exception on /proxies [GET]
Traceback (most recent call last):
  File "C:\Users\admin\AppData\Local\Programs\Python\Python37\lib\site-packages\flask\app.py", line 2073, in wsgi_app
    response = self.full_dispatch_request()
  File "C:\Users\admin\AppData\Local\Programs\Python\Python37\lib\site-packages\flask\app.py", line 1518, in full_dispatch_request
    rv = self.handle_user_exception(e)
  File "C:\Users\admin\AppData\Local\Programs\Python\Python37\lib\site-packages\flask\app.py", line 1516, in full_dispatch_request
    rv = self.dispatch_request()
  File "C:\Users\admin\AppData\Local\Programs\Python\Python37\lib\site-packages\flask\app.py", line 1502, in dispatch_request
    return self.ensure_sync(self.view_functions[rule.endpoint])(**req.view_args)
  File "G:/GITHUB/Proxy/proxy_pool/core/proxy_api.py", line 28, in get_proxies
    proxies = self.mongo_pool.get_proxies(protocol=protocol, nick_type=nick_type, domain=domain, count=count)
  File "G:\GITHUB\Proxy\proxy_pool\utils\mongo_pool.py", line 72, in get_proxies
    for proxy in self.find_sort(conditions=conditions, count=count):
  File "G:\GITHUB\Proxy\proxy_pool\utils\mongo_pool.py", line 52, in find_sort
    proxies = self.proxies.find(filter=conditions, limit=count).sort(
  File "C:\Users\admin\AppData\Local\Programs\Python\Python37\lib\site-packages\pymongo\collection.py", line 1432, in find
    return Cursor(self, *args, **kwargs)
  File "C:\Users\admin\AppData\Local\Programs\Python\Python37\lib\site-packages\pymongo\cursor.py", line 191, in __init__
    raise TypeError("limit must be an instance of int")
TypeError: limit must be an instance of int
2022-03-27 17:07:17 _internal.py [line:225] INFO:127.0.0.1 - - [27/Mar/2022 17:07:17] "[35m[1mGET /proxies HTTP/1.1[0m" 500 -
2022-03-27 17:07:55 _internal.py [line:225] INFO: * Running on http://127.0.0.1:8888/ (Press CTRL+C to quit)
2022-03-27 17:07:59 app.py [line:1458] ERROR:Exception on /proxies [GET]
Traceback (most recent call last):
  File "C:\Users\admin\AppData\Local\Programs\Python\Python37\lib\site-packages\flask\app.py", line 2073, in wsgi_app
    response = self.full_dispatch_request()
  File "C:\Users\admin\AppData\Local\Programs\Python\Python37\lib\site-packages\flask\app.py", line 1518, in full_dispatch_request
    rv = self.handle_user_exception(e)
  File "C:\Users\admin\AppData\Local\Programs\Python\Python37\lib\site-packages\flask\app.py", line 1516, in full_dispatch_request
    rv = self.dispatch_request()
  File "C:\Users\admin\AppData\Local\Programs\Python\Python37\lib\site-packages\flask\app.py", line 1502, in dispatch_request
    return self.ensure_sync(self.view_functions[rule.endpoint])(**req.view_args)
  File "G:/GITHUB/Proxy/proxy_pool/core/proxy_api.py", line 30, in get_proxies
    proxies = self.mongo_pool.get_proxies(protocol=protocol, nick_type=nick_type, domain=domain, count=count)
  File "G:\GITHUB\Proxy\proxy_pool\utils\mongo_pool.py", line 72, in get_proxies
    for proxy in self.find_sort(conditions=conditions, count=count):
  File "G:\GITHUB\Proxy\proxy_pool\utils\mongo_pool.py", line 52, in find_sort
    proxies = self.proxies.find(filter=conditions, limit=count).sort(
  File "C:\Users\admin\AppData\Local\Programs\Python\Python37\lib\site-packages\pymongo\collection.py", line 1432, in find
    return Cursor(self, *args, **kwargs)
  File "C:\Users\admin\AppData\Local\Programs\Python\Python37\lib\site-packages\pymongo\cursor.py", line 191, in __init__
    raise TypeError("limit must be an instance of int")
TypeError: limit must be an instance of int
2022-03-27 17:07:59 _internal.py [line:225] INFO:127.0.0.1 - - [27/Mar/2022 17:07:59] "[35m[1mGET /proxies HTTP/1.1[0m" 500 -
2022-03-27 17:08:03 app.py [line:1458] ERROR:Exception on /proxies [GET]
Traceback (most recent call last):
  File "C:\Users\admin\AppData\Local\Programs\Python\Python37\lib\site-packages\flask\app.py", line 2073, in wsgi_app
    response = self.full_dispatch_request()
  File "C:\Users\admin\AppData\Local\Programs\Python\Python37\lib\site-packages\flask\app.py", line 1518, in full_dispatch_request
    rv = self.handle_user_exception(e)
  File "C:\Users\admin\AppData\Local\Programs\Python\Python37\lib\site-packages\flask\app.py", line 1516, in full_dispatch_request
    rv = self.dispatch_request()
  File "C:\Users\admin\AppData\Local\Programs\Python\Python37\lib\site-packages\flask\app.py", line 1502, in dispatch_request
    return self.ensure_sync(self.view_functions[rule.endpoint])(**req.view_args)
  File "G:/GITHUB/Proxy/proxy_pool/core/proxy_api.py", line 30, in get_proxies
    proxies = self.mongo_pool.get_proxies(protocol=protocol, nick_type=nick_type, domain=domain, count=count)
  File "G:\GITHUB\Proxy\proxy_pool\utils\mongo_pool.py", line 72, in get_proxies
    for proxy in self.find_sort(conditions=conditions, count=count):
  File "G:\GITHUB\Proxy\proxy_pool\utils\mongo_pool.py", line 52, in find_sort
    proxies = self.proxies.find(filter=conditions, limit=count).sort(
  File "C:\Users\admin\AppData\Local\Programs\Python\Python37\lib\site-packages\pymongo\collection.py", line 1432, in find
    return Cursor(self, *args, **kwargs)
  File "C:\Users\admin\AppData\Local\Programs\Python\Python37\lib\site-packages\pymongo\cursor.py", line 191, in __init__
    raise TypeError("limit must be an instance of int")
TypeError: limit must be an instance of int
2022-03-27 17:08:03 _internal.py [line:225] INFO:127.0.0.1 - - [27/Mar/2022 17:08:03] "[35m[1mGET /proxies HTTP/1.1[0m" 500 -
2022-03-27 17:08:28 _internal.py [line:225] INFO:127.0.0.1 - - [27/Mar/2022 17:08:28] "[33mGET /favicon.ico HTTP/1.1[0m" 404 -
2022-03-27 17:08:28 _internal.py [line:225] INFO:127.0.0.1 - - [27/Mar/2022 17:08:28] "[33mGET /favicon.ico HTTP/1.1[0m" 404 -
2022-03-27 17:08:29 _internal.py [line:225] INFO:127.0.0.1 - - [27/Mar/2022 17:08:29] "[33mGET /favicon.ico HTTP/1.1[0m" 404 -
2022-03-27 17:08:29 _internal.py [line:225] INFO:127.0.0.1 - - [27/Mar/2022 17:08:29] "GET /disable_domain HTTP/1.1" 200 -
2022-03-27 17:08:54 _internal.py [line:225] INFO:127.0.0.1 - - [27/Mar/2022 17:08:54] "[33mGET /favicon.ico HTTP/1.1[0m" 404 -
2022-03-27 17:08:54 _internal.py [line:225] INFO:127.0.0.1 - - [27/Mar/2022 17:08:54] "[33mGET /favicon.ico HTTP/1.1[0m" 404 -
2022-03-27 17:08:55 app.py [line:1458] ERROR:Exception on /random [GET]
Traceback (most recent call last):
  File "C:\Users\admin\AppData\Local\Programs\Python\Python37\lib\site-packages\flask\app.py", line 2073, in wsgi_app
    response = self.full_dispatch_request()
  File "C:\Users\admin\AppData\Local\Programs\Python\Python37\lib\site-packages\flask\app.py", line 1518, in full_dispatch_request
    rv = self.handle_user_exception(e)
  File "C:\Users\admin\AppData\Local\Programs\Python\Python37\lib\site-packages\flask\app.py", line 1516, in full_dispatch_request
    rv = self.dispatch_request()
  File "C:\Users\admin\AppData\Local\Programs\Python\Python37\lib\site-packages\flask\app.py", line 1502, in dispatch_request
    return self.ensure_sync(self.view_functions[rule.endpoint])(**req.view_args)
  File "G:/GITHUB/Proxy/proxy_pool/core/proxy_api.py", line 18, in random_proxy
    proxy = self.mongo_pool.get_one_random_proxy(protocol=protocol, nick_type=nick_type, domain=domain)
  File "G:\GITHUB\Proxy\proxy_pool\utils\mongo_pool.py", line 77, in get_one_random_proxy
    return random.choice(self.get_proxies(protocol=protocol, nick_type=nick_type, domain=domain, count=count))
  File "C:\Users\admin\AppData\Local\Programs\Python\Python37\lib\random.py", line 261, in choice
    raise IndexError('Cannot choose from an empty sequence') from None
IndexError: Cannot choose from an empty sequence
2022-03-27 17:08:55 _internal.py [line:225] INFO:127.0.0.1 - - [27/Mar/2022 17:08:55] "[35m[1mGET /random HTTP/1.1[0m" 500 -
2022-03-27 17:09:18 _internal.py [line:225] INFO:127.0.0.1 - - [27/Mar/2022 17:09:18] "[33mGET /favicon.ico HTTP/1.1[0m" 404 -
2022-03-27 17:09:18 _internal.py [line:225] INFO:127.0.0.1 - - [27/Mar/2022 17:09:18] "[33mGET /favicon.ico HTTP/1.1[0m" 404 -
2022-03-27 17:09:19 _internal.py [line:225] INFO:127.0.0.1 - - [27/Mar/2022 17:09:19] "[33mGET /favicon.ico HTTP/1.1[0m" 404 -
2022-03-27 17:09:19 _internal.py [line:225] INFO:127.0.0.1 - - [27/Mar/2022 17:09:19] "[33mGET /favicon.ico HTTP/1.1[0m" 404 -
2022-03-27 17:09:20 _internal.py [line:225] INFO:127.0.0.1 - - [27/Mar/2022 17:09:20] "[33mGET /favicon.ico HTTP/1.1[0m" 404 -
2022-03-27 17:09:21 _internal.py [line:225] INFO:127.0.0.1 - - [27/Mar/2022 17:09:21] "[33mGET /favicon.ico HTTP/1.1[0m" 404 -
2022-03-27 17:09:21 _internal.py [line:225] INFO:127.0.0.1 - - [27/Mar/2022 17:09:21] "[33mGET /random/ HTTP/1.1[0m" 404 -
2022-03-27 17:09:25 _internal.py [line:225] INFO:127.0.0.1 - - [27/Mar/2022 17:09:25] "[33mGET /favicon.ico HTTP/1.1[0m" 404 -
2022-03-27 17:09:25 app.py [line:1458] ERROR:Exception on /random [GET]
Traceback (most recent call last):
  File "C:\Users\admin\AppData\Local\Programs\Python\Python37\lib\site-packages\flask\app.py", line 2073, in wsgi_app
    response = self.full_dispatch_request()
  File "C:\Users\admin\AppData\Local\Programs\Python\Python37\lib\site-packages\flask\app.py", line 1518, in full_dispatch_request
    rv = self.handle_user_exception(e)
  File "C:\Users\admin\AppData\Local\Programs\Python\Python37\lib\site-packages\flask\app.py", line 1516, in full_dispatch_request
    rv = self.dispatch_request()
  File "C:\Users\admin\AppData\Local\Programs\Python\Python37\lib\site-packages\flask\app.py", line 1502, in dispatch_request
    return self.ensure_sync(self.view_functions[rule.endpoint])(**req.view_args)
  File "G:/GITHUB/Proxy/proxy_pool/core/proxy_api.py", line 18, in random_proxy
    proxy = self.mongo_pool.get_one_random_proxy(protocol=protocol, nick_type=nick_type, domain=domain)
  File "G:\GITHUB\Proxy\proxy_pool\utils\mongo_pool.py", line 77, in get_one_random_proxy
    return random.choice(self.get_proxies(protocol=protocol, nick_type=nick_type, domain=domain, count=count))
  File "C:\Users\admin\AppData\Local\Programs\Python\Python37\lib\random.py", line 261, in choice
    raise IndexError('Cannot choose from an empty sequence') from None
IndexError: Cannot choose from an empty sequence
2022-03-27 17:09:25 _internal.py [line:225] INFO:127.0.0.1 - - [27/Mar/2022 17:09:25] "[35m[1mGET /random HTTP/1.1[0m" 500 -
2022-03-27 17:09:38 _internal.py [line:225] INFO:127.0.0.1 - - [27/Mar/2022 17:09:38] "[33mGET / HTTP/1.1[0m" 404 -
2022-03-27 17:09:38 _internal.py [line:225] INFO:127.0.0.1 - - [27/Mar/2022 17:09:38] "[33mGET /favicon.ico HTTP/1.1[0m" 404 -
2022-03-27 17:09:43 app.py [line:1458] ERROR:Exception on /random [GET]
Traceback (most recent call last):
  File "C:\Users\admin\AppData\Local\Programs\Python\Python37\lib\site-packages\flask\app.py", line 2073, in wsgi_app
    response = self.full_dispatch_request()
  File "C:\Users\admin\AppData\Local\Programs\Python\Python37\lib\site-packages\flask\app.py", line 1518, in full_dispatch_request
    rv = self.handle_user_exception(e)
  File "C:\Users\admin\AppData\Local\Programs\Python\Python37\lib\site-packages\flask\app.py", line 1516, in full_dispatch_request
    rv = self.dispatch_request()
  File "C:\Users\admin\AppData\Local\Programs\Python\Python37\lib\site-packages\flask\app.py", line 1502, in dispatch_request
    return self.ensure_sync(self.view_functions[rule.endpoint])(**req.view_args)
  File "G:/GITHUB/Proxy/proxy_pool/core/proxy_api.py", line 18, in random_proxy
    proxy = self.mongo_pool.get_one_random_proxy(protocol=protocol, nick_type=nick_type, domain=domain)
  File "G:\GITHUB\Proxy\proxy_pool\utils\mongo_pool.py", line 77, in get_one_random_proxy
    return random.choice(self.get_proxies(protocol=protocol, nick_type=nick_type, domain=domain, count=count))
  File "C:\Users\admin\AppData\Local\Programs\Python\Python37\lib\random.py", line 261, in choice
    raise IndexError('Cannot choose from an empty sequence') from None
IndexError: Cannot choose from an empty sequence
2022-03-27 17:09:43 _internal.py [line:225] INFO:127.0.0.1 - - [27/Mar/2022 17:09:43] "[35m[1mGET /random HTTP/1.1[0m" 500 -
2022-03-27 17:09:47 _internal.py [line:225] INFO:127.0.0.1 - - [27/Mar/2022 17:09:47] "[33mGET /random/ HTTP/1.1[0m" 404 -
2022-03-27 17:09:50 app.py [line:1458] ERROR:Exception on /random [GET]
Traceback (most recent call last):
  File "C:\Users\admin\AppData\Local\Programs\Python\Python37\lib\site-packages\flask\app.py", line 2073, in wsgi_app
    response = self.full_dispatch_request()
  File "C:\Users\admin\AppData\Local\Programs\Python\Python37\lib\site-packages\flask\app.py", line 1518, in full_dispatch_request
    rv = self.handle_user_exception(e)
  File "C:\Users\admin\AppData\Local\Programs\Python\Python37\lib\site-packages\flask\app.py", line 1516, in full_dispatch_request
    rv = self.dispatch_request()
  File "C:\Users\admin\AppData\Local\Programs\Python\Python37\lib\site-packages\flask\app.py", line 1502, in dispatch_request
    return self.ensure_sync(self.view_functions[rule.endpoint])(**req.view_args)
  File "G:/GITHUB/Proxy/proxy_pool/core/proxy_api.py", line 18, in random_proxy
    proxy = self.mongo_pool.get_one_random_proxy(protocol=protocol, nick_type=nick_type, domain=domain)
  File "G:\GITHUB\Proxy\proxy_pool\utils\mongo_pool.py", line 77, in get_one_random_proxy
    return random.choice(self.get_proxies(protocol=protocol, nick_type=nick_type, domain=domain, count=count))
  File "C:\Users\admin\AppData\Local\Programs\Python\Python37\lib\random.py", line 261, in choice
    raise IndexError('Cannot choose from an empty sequence') from None
IndexError: Cannot choose from an empty sequence
2022-03-27 17:09:50 _internal.py [line:225] INFO:127.0.0.1 - - [27/Mar/2022 17:09:50] "[35m[1mGET /random HTTP/1.1[0m" 500 -
2022-03-27 17:11:08 app.py [line:1458] ERROR:Exception on /random [GET]
Traceback (most recent call last):
  File "C:\Users\admin\AppData\Local\Programs\Python\Python37\lib\site-packages\flask\app.py", line 2073, in wsgi_app
    response = self.full_dispatch_request()
  File "C:\Users\admin\AppData\Local\Programs\Python\Python37\lib\site-packages\flask\app.py", line 1518, in full_dispatch_request
    rv = self.handle_user_exception(e)
  File "C:\Users\admin\AppData\Local\Programs\Python\Python37\lib\site-packages\flask\app.py", line 1516, in full_dispatch_request
    rv = self.dispatch_request()
  File "C:\Users\admin\AppData\Local\Programs\Python\Python37\lib\site-packages\flask\app.py", line 1502, in dispatch_request
    return self.ensure_sync(self.view_functions[rule.endpoint])(**req.view_args)
  File "G:/GITHUB/Proxy/proxy_pool/core/proxy_api.py", line 18, in random_proxy
    proxy = self.mongo_pool.get_one_random_proxy(protocol=protocol, nick_type=nick_type, domain=domain)
  File "G:\GITHUB\Proxy\proxy_pool\utils\mongo_pool.py", line 77, in get_one_random_proxy
    return random.choice(self.get_proxies(protocol=protocol, nick_type=nick_type, domain=domain, count=count))
  File "C:\Users\admin\AppData\Local\Programs\Python\Python37\lib\random.py", line 261, in choice
    raise IndexError('Cannot choose from an empty sequence') from None
IndexError: Cannot choose from an empty sequence
2022-03-27 17:11:08 _internal.py [line:225] INFO:127.0.0.1 - - [27/Mar/2022 17:11:08] "[35m[1mGET /random?protocol=1 HTTP/1.1[0m" 500 -
2022-03-27 17:11:12 app.py [line:1458] ERROR:Exception on /random [GET]
Traceback (most recent call last):
  File "C:\Users\admin\AppData\Local\Programs\Python\Python37\lib\site-packages\flask\app.py", line 2073, in wsgi_app
    response = self.full_dispatch_request()
  File "C:\Users\admin\AppData\Local\Programs\Python\Python37\lib\site-packages\flask\app.py", line 1518, in full_dispatch_request
    rv = self.handle_user_exception(e)
  File "C:\Users\admin\AppData\Local\Programs\Python\Python37\lib\site-packages\flask\app.py", line 1516, in full_dispatch_request
    rv = self.dispatch_request()
  File "C:\Users\admin\AppData\Local\Programs\Python\Python37\lib\site-packages\flask\app.py", line 1502, in dispatch_request
    return self.ensure_sync(self.view_functions[rule.endpoint])(**req.view_args)
  File "G:/GITHUB/Proxy/proxy_pool/core/proxy_api.py", line 18, in random_proxy
    proxy = self.mongo_pool.get_one_random_proxy(protocol=protocol, nick_type=nick_type, domain=domain)
  File "G:\GITHUB\Proxy\proxy_pool\utils\mongo_pool.py", line 77, in get_one_random_proxy
    return random.choice(self.get_proxies(protocol=protocol, nick_type=nick_type, domain=domain, count=count))
  File "C:\Users\admin\AppData\Local\Programs\Python\Python37\lib\random.py", line 261, in choice
    raise IndexError('Cannot choose from an empty sequence') from None
IndexError: Cannot choose from an empty sequence
2022-03-27 17:11:12 _internal.py [line:225] INFO:127.0.0.1 - - [27/Mar/2022 17:11:12] "[35m[1mGET /random?protocol=2 HTTP/1.1[0m" 500 -
2022-03-27 17:11:32 app.py [line:1458] ERROR:Exception on /random [GET]
Traceback (most recent call last):
  File "C:\Users\admin\AppData\Local\Programs\Python\Python37\lib\site-packages\flask\app.py", line 2073, in wsgi_app
    response = self.full_dispatch_request()
  File "C:\Users\admin\AppData\Local\Programs\Python\Python37\lib\site-packages\flask\app.py", line 1518, in full_dispatch_request
    rv = self.handle_user_exception(e)
  File "C:\Users\admin\AppData\Local\Programs\Python\Python37\lib\site-packages\flask\app.py", line 1516, in full_dispatch_request
    rv = self.dispatch_request()
  File "C:\Users\admin\AppData\Local\Programs\Python\Python37\lib\site-packages\flask\app.py", line 1502, in dispatch_request
    return self.ensure_sync(self.view_functions[rule.endpoint])(**req.view_args)
  File "G:/GITHUB/Proxy/proxy_pool/core/proxy_api.py", line 18, in random_proxy
    proxy = self.mongo_pool.get_one_random_proxy(protocol=protocol, nick_type=nick_type, domain=domain)
  File "G:\GITHUB\Proxy\proxy_pool\utils\mongo_pool.py", line 77, in get_one_random_proxy
    return random.choice(self.get_proxies(protocol=protocol, nick_type=nick_type, domain=domain, count=count))
  File "C:\Users\admin\AppData\Local\Programs\Python\Python37\lib\random.py", line 261, in choice
    raise IndexError('Cannot choose from an empty sequence') from None
IndexError: Cannot choose from an empty sequence
2022-03-27 17:11:32 _internal.py [line:225] INFO:127.0.0.1 - - [27/Mar/2022 17:11:32] "[35m[1mGET /random?protocol=0 HTTP/1.1[0m" 500 -
2022-03-27 17:12:33 _internal.py [line:225] INFO: * Running on http://127.0.0.1:8888/ (Press CTRL+C to quit)
2022-03-27 17:12:44 app.py [line:1458] ERROR:Exception on /random [GET]
Traceback (most recent call last):
  File "C:\Users\admin\AppData\Local\Programs\Python\Python37\lib\site-packages\flask\app.py", line 2073, in wsgi_app
    response = self.full_dispatch_request()
  File "C:\Users\admin\AppData\Local\Programs\Python\Python37\lib\site-packages\flask\app.py", line 1518, in full_dispatch_request
    rv = self.handle_user_exception(e)
  File "C:\Users\admin\AppData\Local\Programs\Python\Python37\lib\site-packages\flask\app.py", line 1516, in full_dispatch_request
    rv = self.dispatch_request()
  File "C:\Users\admin\AppData\Local\Programs\Python\Python37\lib\site-packages\flask\app.py", line 1502, in dispatch_request
    return self.ensure_sync(self.view_functions[rule.endpoint])(**req.view_args)
  File "G:/GITHUB/Proxy/proxy_pool/core/proxy_api.py", line 15, in random_proxy
    print(request.args())
TypeError: 'ImmutableMultiDict' object is not callable
2022-03-27 17:12:44 _internal.py [line:225] INFO:127.0.0.1 - - [27/Mar/2022 17:12:44] "[35m[1mGET /random?protocol=0 HTTP/1.1[0m" 500 -
2022-03-27 17:12:45 app.py [line:1458] ERROR:Exception on /random [GET]
Traceback (most recent call last):
  File "C:\Users\admin\AppData\Local\Programs\Python\Python37\lib\site-packages\flask\app.py", line 2073, in wsgi_app
    response = self.full_dispatch_request()
  File "C:\Users\admin\AppData\Local\Programs\Python\Python37\lib\site-packages\flask\app.py", line 1518, in full_dispatch_request
    rv = self.handle_user_exception(e)
  File "C:\Users\admin\AppData\Local\Programs\Python\Python37\lib\site-packages\flask\app.py", line 1516, in full_dispatch_request
    rv = self.dispatch_request()
  File "C:\Users\admin\AppData\Local\Programs\Python\Python37\lib\site-packages\flask\app.py", line 1502, in dispatch_request
    return self.ensure_sync(self.view_functions[rule.endpoint])(**req.view_args)
  File "G:/GITHUB/Proxy/proxy_pool/core/proxy_api.py", line 15, in random_proxy
    print(request.args())
TypeError: 'ImmutableMultiDict' object is not callable
2022-03-27 17:12:45 _internal.py [line:225] INFO:127.0.0.1 - - [27/Mar/2022 17:12:45] "[35m[1mGET /random?protocol=0 HTTP/1.1[0m" 500 -
2022-03-27 17:12:46 app.py [line:1458] ERROR:Exception on /random [GET]
Traceback (most recent call last):
  File "C:\Users\admin\AppData\Local\Programs\Python\Python37\lib\site-packages\flask\app.py", line 2073, in wsgi_app
    response = self.full_dispatch_request()
  File "C:\Users\admin\AppData\Local\Programs\Python\Python37\lib\site-packages\flask\app.py", line 1518, in full_dispatch_request
    rv = self.handle_user_exception(e)
  File "C:\Users\admin\AppData\Local\Programs\Python\Python37\lib\site-packages\flask\app.py", line 1516, in full_dispatch_request
    rv = self.dispatch_request()
  File "C:\Users\admin\AppData\Local\Programs\Python\Python37\lib\site-packages\flask\app.py", line 1502, in dispatch_request
    return self.ensure_sync(self.view_functions[rule.endpoint])(**req.view_args)
  File "G:/GITHUB/Proxy/proxy_pool/core/proxy_api.py", line 15, in random_proxy
    print(request.args())
TypeError: 'ImmutableMultiDict' object is not callable
2022-03-27 17:12:46 _internal.py [line:225] INFO:127.0.0.1 - - [27/Mar/2022 17:12:46] "[35m[1mGET /random?protocol=0 HTTP/1.1[0m" 500 -
2022-03-27 17:12:48 app.py [line:1458] ERROR:Exception on /random [GET]
Traceback (most recent call last):
  File "C:\Users\admin\AppData\Local\Programs\Python\Python37\lib\site-packages\flask\app.py", line 2073, in wsgi_app
    response = self.full_dispatch_request()
  File "C:\Users\admin\AppData\Local\Programs\Python\Python37\lib\site-packages\flask\app.py", line 1518, in full_dispatch_request
    rv = self.handle_user_exception(e)
  File "C:\Users\admin\AppData\Local\Programs\Python\Python37\lib\site-packages\flask\app.py", line 1516, in full_dispatch_request
    rv = self.dispatch_request()
  File "C:\Users\admin\AppData\Local\Programs\Python\Python37\lib\site-packages\flask\app.py", line 1502, in dispatch_request
    return self.ensure_sync(self.view_functions[rule.endpoint])(**req.view_args)
  File "G:/GITHUB/Proxy/proxy_pool/core/proxy_api.py", line 15, in random_proxy
    print(request.args())
TypeError: 'ImmutableMultiDict' object is not callable
2022-03-27 17:12:48 _internal.py [line:225] INFO:127.0.0.1 - - [27/Mar/2022 17:12:48] "[35m[1mGET /random HTTP/1.1[0m" 500 -
2022-03-27 17:13:00 app.py [line:1458] ERROR:Exception on /random [GET]
Traceback (most recent call last):
  File "C:\Users\admin\AppData\Local\Programs\Python\Python37\lib\site-packages\flask\app.py", line 2073, in wsgi_app
    response = self.full_dispatch_request()
  File "C:\Users\admin\AppData\Local\Programs\Python\Python37\lib\site-packages\flask\app.py", line 1518, in full_dispatch_request
    rv = self.handle_user_exception(e)
  File "C:\Users\admin\AppData\Local\Programs\Python\Python37\lib\site-packages\flask\app.py", line 1516, in full_dispatch_request
    rv = self.dispatch_request()
  File "C:\Users\admin\AppData\Local\Programs\Python\Python37\lib\site-packages\flask\app.py", line 1502, in dispatch_request
    return self.ensure_sync(self.view_functions[rule.endpoint])(**req.view_args)
  File "G:/GITHUB/Proxy/proxy_pool/core/proxy_api.py", line 15, in random_proxy
    print(request.args())
TypeError: 'ImmutableMultiDict' object is not callable
2022-03-27 17:13:00 _internal.py [line:225] INFO:127.0.0.1 - - [27/Mar/2022 17:13:00] "[35m[1mGET /random HTTP/1.1[0m" 500 -
2022-03-27 17:13:25 _internal.py [line:225] INFO: * Running on http://127.0.0.1:8888/ (Press CTRL+C to quit)
2022-03-27 17:15:53 _internal.py [line:225] INFO: * Running on http://127.0.0.1:8888/ (Press CTRL+C to quit)
2022-03-27 17:15:58 _internal.py [line:225] INFO:127.0.0.1 - - [27/Mar/2022 17:15:58] "GET / HTTP/1.1" 200 -
2022-03-27 17:15:59 _internal.py [line:225] INFO:127.0.0.1 - - [27/Mar/2022 17:15:59] "[33mGET /favicon.ico HTTP/1.1[0m" 404 -
2022-03-27 17:22:52 _internal.py [line:225] INFO:127.0.0.1 - - [27/Mar/2022 17:22:52] "GET / HTTP/1.1" 200 -
2022-03-27 17:22:53 _internal.py [line:225] INFO:127.0.0.1 - - [27/Mar/2022 17:22:53] "[33mGET /favicon.ico HTTP/1.1[0m" 404 -
2022-03-27 17:23:08 app.py [line:1458] ERROR:Exception on /proxies [GET]
Traceback (most recent call last):
  File "C:\Users\admin\AppData\Local\Programs\Python\Python37\lib\site-packages\flask\app.py", line 2073, in wsgi_app
    response = self.full_dispatch_request()
  File "C:\Users\admin\AppData\Local\Programs\Python\Python37\lib\site-packages\flask\app.py", line 1518, in full_dispatch_request
    rv = self.handle_user_exception(e)
  File "C:\Users\admin\AppData\Local\Programs\Python\Python37\lib\site-packages\flask\app.py", line 1516, in full_dispatch_request
    rv = self.dispatch_request()
  File "C:\Users\admin\AppData\Local\Programs\Python\Python37\lib\site-packages\flask\app.py", line 1502, in dispatch_request
    return self.ensure_sync(self.view_functions[rule.endpoint])(**req.view_args)
  File "G:/GITHUB/Proxy/proxy_pool/core/proxy_api.py", line 34, in get_proxies
    proxies = self.mongo_pool.get_proxies(protocol=protocol, nick_type=nick_type, domain=domain, count=count)
  File "G:\GITHUB\Proxy\proxy_pool\utils\mongo_pool.py", line 72, in get_proxies
    for proxy in self.find_sort(conditions=conditions, count=count):
  File "G:\GITHUB\Proxy\proxy_pool\utils\mongo_pool.py", line 52, in find_sort
    proxies = self.proxies.find(filter=conditions, limit=count).sort(
  File "C:\Users\admin\AppData\Local\Programs\Python\Python37\lib\site-packages\pymongo\collection.py", line 1432, in find
    return Cursor(self, *args, **kwargs)
  File "C:\Users\admin\AppData\Local\Programs\Python\Python37\lib\site-packages\pymongo\cursor.py", line 191, in __init__
    raise TypeError("limit must be an instance of int")
TypeError: limit must be an instance of int
2022-03-27 17:23:08 _internal.py [line:225] INFO:127.0.0.1 - - [27/Mar/2022 17:23:08] "[35m[1mGET /proxies HTTP/1.1[0m" 500 -
2022-03-27 17:24:12 _internal.py [line:225] INFO: * Running on http://127.0.0.1:8888/ (Press CTRL+C to quit)
2022-03-27 17:24:16 app.py [line:1458] ERROR:Exception on /proxies [GET]
Traceback (most recent call last):
  File "C:\Users\admin\AppData\Local\Programs\Python\Python37\lib\site-packages\flask\app.py", line 2073, in wsgi_app
    response = self.full_dispatch_request()
  File "C:\Users\admin\AppData\Local\Programs\Python\Python37\lib\site-packages\flask\app.py", line 1518, in full_dispatch_request
    rv = self.handle_user_exception(e)
  File "C:\Users\admin\AppData\Local\Programs\Python\Python37\lib\site-packages\flask\app.py", line 1516, in full_dispatch_request
    rv = self.dispatch_request()
  File "C:\Users\admin\AppData\Local\Programs\Python\Python37\lib\site-packages\flask\app.py", line 1502, in dispatch_request
    return self.ensure_sync(self.view_functions[rule.endpoint])(**req.view_args)
  File "G:/GITHUB/Proxy/proxy_pool/core/proxy_api.py", line 34, in get_proxies
    proxies = self.mongo_pool.get_proxies(protocol=protocol, nick_type=nick_type, domain=domain, count=count)
  File "G:\GITHUB\Proxy\proxy_pool\utils\mongo_pool.py", line 72, in get_proxies
    for proxy in self.find_sort(conditions=conditions, count=count):
  File "G:\GITHUB\Proxy\proxy_pool\utils\mongo_pool.py", line 52, in find_sort
    proxies = self.proxies.find(filter=conditions, limit=count).sort(
  File "C:\Users\admin\AppData\Local\Programs\Python\Python37\lib\site-packages\pymongo\collection.py", line 1432, in find
    return Cursor(self, *args, **kwargs)
  File "C:\Users\admin\AppData\Local\Programs\Python\Python37\lib\site-packages\pymongo\cursor.py", line 191, in __init__
    raise TypeError("limit must be an instance of int")
TypeError: limit must be an instance of int
2022-03-27 17:24:16 _internal.py [line:225] INFO:127.0.0.1 - - [27/Mar/2022 17:24:16] "[35m[1mGET /proxies HTTP/1.1[0m" 500 -
2022-03-27 17:24:17 app.py [line:1458] ERROR:Exception on /proxies [GET]
Traceback (most recent call last):
  File "C:\Users\admin\AppData\Local\Programs\Python\Python37\lib\site-packages\flask\app.py", line 2073, in wsgi_app
    response = self.full_dispatch_request()
  File "C:\Users\admin\AppData\Local\Programs\Python\Python37\lib\site-packages\flask\app.py", line 1518, in full_dispatch_request
    rv = self.handle_user_exception(e)
  File "C:\Users\admin\AppData\Local\Programs\Python\Python37\lib\site-packages\flask\app.py", line 1516, in full_dispatch_request
    rv = self.dispatch_request()
  File "C:\Users\admin\AppData\Local\Programs\Python\Python37\lib\site-packages\flask\app.py", line 1502, in dispatch_request
    return self.ensure_sync(self.view_functions[rule.endpoint])(**req.view_args)
  File "G:/GITHUB/Proxy/proxy_pool/core/proxy_api.py", line 34, in get_proxies
    proxies = self.mongo_pool.get_proxies(protocol=protocol, nick_type=nick_type, domain=domain, count=count)
  File "G:\GITHUB\Proxy\proxy_pool\utils\mongo_pool.py", line 72, in get_proxies
    for proxy in self.find_sort(conditions=conditions, count=count):
  File "G:\GITHUB\Proxy\proxy_pool\utils\mongo_pool.py", line 52, in find_sort
    proxies = self.proxies.find(filter=conditions, limit=count).sort(
  File "C:\Users\admin\AppData\Local\Programs\Python\Python37\lib\site-packages\pymongo\collection.py", line 1432, in find
    return Cursor(self, *args, **kwargs)
  File "C:\Users\admin\AppData\Local\Programs\Python\Python37\lib\site-packages\pymongo\cursor.py", line 191, in __init__
    raise TypeError("limit must be an instance of int")
TypeError: limit must be an instance of int
2022-03-27 17:24:17 _internal.py [line:225] INFO:127.0.0.1 - - [27/Mar/2022 17:24:17] "[35m[1mGET /proxies HTTP/1.1[0m" 500 -
2022-03-27 17:24:20 app.py [line:1458] ERROR:Exception on /proxies [GET]
Traceback (most recent call last):
  File "C:\Users\admin\AppData\Local\Programs\Python\Python37\lib\site-packages\flask\app.py", line 2073, in wsgi_app
    response = self.full_dispatch_request()
  File "C:\Users\admin\AppData\Local\Programs\Python\Python37\lib\site-packages\flask\app.py", line 1518, in full_dispatch_request
    rv = self.handle_user_exception(e)
  File "C:\Users\admin\AppData\Local\Programs\Python\Python37\lib\site-packages\flask\app.py", line 1516, in full_dispatch_request
    rv = self.dispatch_request()
  File "C:\Users\admin\AppData\Local\Programs\Python\Python37\lib\site-packages\flask\app.py", line 1502, in dispatch_request
    return self.ensure_sync(self.view_functions[rule.endpoint])(**req.view_args)
  File "G:/GITHUB/Proxy/proxy_pool/core/proxy_api.py", line 34, in get_proxies
    proxies = self.mongo_pool.get_proxies(protocol=protocol, nick_type=nick_type, domain=domain, count=count)
  File "G:\GITHUB\Proxy\proxy_pool\utils\mongo_pool.py", line 72, in get_proxies
    for proxy in self.find_sort(conditions=conditions, count=count):
  File "G:\GITHUB\Proxy\proxy_pool\utils\mongo_pool.py", line 52, in find_sort
    proxies = self.proxies.find(filter=conditions, limit=count).sort(
  File "C:\Users\admin\AppData\Local\Programs\Python\Python37\lib\site-packages\pymongo\collection.py", line 1432, in find
    return Cursor(self, *args, **kwargs)
  File "C:\Users\admin\AppData\Local\Programs\Python\Python37\lib\site-packages\pymongo\cursor.py", line 191, in __init__
    raise TypeError("limit must be an instance of int")
TypeError: limit must be an instance of int
2022-03-27 17:24:20 _internal.py [line:225] INFO:127.0.0.1 - - [27/Mar/2022 17:24:20] "[35m[1mGET /proxies HTTP/1.1[0m" 500 -
2022-03-27 17:24:28 app.py [line:1458] ERROR:Exception on /proxies [GET]
Traceback (most recent call last):
  File "C:\Users\admin\AppData\Local\Programs\Python\Python37\lib\site-packages\flask\app.py", line 2073, in wsgi_app
    response = self.full_dispatch_request()
  File "C:\Users\admin\AppData\Local\Programs\Python\Python37\lib\site-packages\flask\app.py", line 1518, in full_dispatch_request
    rv = self.handle_user_exception(e)
  File "C:\Users\admin\AppData\Local\Programs\Python\Python37\lib\site-packages\flask\app.py", line 1516, in full_dispatch_request
    rv = self.dispatch_request()
  File "C:\Users\admin\AppData\Local\Programs\Python\Python37\lib\site-packages\flask\app.py", line 1502, in dispatch_request
    return self.ensure_sync(self.view_functions[rule.endpoint])(**req.view_args)
  File "G:/GITHUB/Proxy/proxy_pool/core/proxy_api.py", line 34, in get_proxies
    proxies = self.mongo_pool.get_proxies(protocol=protocol, nick_type=nick_type, domain=domain, count=count)
  File "G:\GITHUB\Proxy\proxy_pool\utils\mongo_pool.py", line 72, in get_proxies
    for proxy in self.find_sort(conditions=conditions, count=count):
  File "G:\GITHUB\Proxy\proxy_pool\utils\mongo_pool.py", line 52, in find_sort
    proxies = self.proxies.find(filter=conditions, limit=count).sort(
  File "C:\Users\admin\AppData\Local\Programs\Python\Python37\lib\site-packages\pymongo\collection.py", line 1432, in find
    return Cursor(self, *args, **kwargs)
  File "C:\Users\admin\AppData\Local\Programs\Python\Python37\lib\site-packages\pymongo\cursor.py", line 191, in __init__
    raise TypeError("limit must be an instance of int")
TypeError: limit must be an instance of int
2022-03-27 17:24:28 _internal.py [line:225] INFO:127.0.0.1 - - [27/Mar/2022 17:24:28] "[35m[1mGET /proxies HTTP/1.1[0m" 500 -
2022-03-27 17:25:47 _internal.py [line:225] INFO: * Running on http://127.0.0.1:8888/ (Press CTRL+C to quit)
2022-03-27 17:25:54 app.py [line:1458] ERROR:Exception on /proxies [GET]
Traceback (most recent call last):
  File "C:\Users\admin\AppData\Local\Programs\Python\Python37\lib\site-packages\flask\app.py", line 2073, in wsgi_app
    response = self.full_dispatch_request()
  File "C:\Users\admin\AppData\Local\Programs\Python\Python37\lib\site-packages\flask\app.py", line 1518, in full_dispatch_request
    rv = self.handle_user_exception(e)
  File "C:\Users\admin\AppData\Local\Programs\Python\Python37\lib\site-packages\flask\app.py", line 1516, in full_dispatch_request
    rv = self.dispatch_request()
  File "C:\Users\admin\AppData\Local\Programs\Python\Python37\lib\site-packages\flask\app.py", line 1502, in dispatch_request
    return self.ensure_sync(self.view_functions[rule.endpoint])(**req.view_args)
  File "G:/GITHUB/Proxy/proxy_pool/core/proxy_api.py", line 34, in get_proxies
    proxies = self.mongo_pool.get_proxies(protocol=protocol, nick_type=nick_type, domain=domain, count=count)
  File "G:\GITHUB\Proxy\proxy_pool\utils\mongo_pool.py", line 72, in get_proxies
    for proxy in self.find_sort(conditions=conditions, count=count):
  File "G:\GITHUB\Proxy\proxy_pool\utils\mongo_pool.py", line 52, in find_sort
    proxies = self.proxies.find(filter=conditions, limit=count).sort(
  File "C:\Users\admin\AppData\Local\Programs\Python\Python37\lib\site-packages\pymongo\collection.py", line 1432, in find
    return Cursor(self, *args, **kwargs)
  File "C:\Users\admin\AppData\Local\Programs\Python\Python37\lib\site-packages\pymongo\cursor.py", line 191, in __init__
    raise TypeError("limit must be an instance of int")
TypeError: limit must be an instance of int
2022-03-27 17:25:54 _internal.py [line:225] INFO:127.0.0.1 - - [27/Mar/2022 17:25:54] "[35m[1mGET /proxies HTTP/1.1[0m" 500 -
2022-03-27 17:26:03 app.py [line:1458] ERROR:Exception on /proxies [GET]
Traceback (most recent call last):
  File "C:\Users\admin\AppData\Local\Programs\Python\Python37\lib\site-packages\flask\app.py", line 2073, in wsgi_app
    response = self.full_dispatch_request()
  File "C:\Users\admin\AppData\Local\Programs\Python\Python37\lib\site-packages\flask\app.py", line 1518, in full_dispatch_request
    rv = self.handle_user_exception(e)
  File "C:\Users\admin\AppData\Local\Programs\Python\Python37\lib\site-packages\flask\app.py", line 1516, in full_dispatch_request
    rv = self.dispatch_request()
  File "C:\Users\admin\AppData\Local\Programs\Python\Python37\lib\site-packages\flask\app.py", line 1502, in dispatch_request
    return self.ensure_sync(self.view_functions[rule.endpoint])(**req.view_args)
  File "G:/GITHUB/Proxy/proxy_pool/core/proxy_api.py", line 34, in get_proxies
    proxies = self.mongo_pool.get_proxies(protocol=protocol, nick_type=nick_type, domain=domain, count=count)
  File "G:\GITHUB\Proxy\proxy_pool\utils\mongo_pool.py", line 72, in get_proxies
    for proxy in self.find_sort(conditions=conditions, count=count):
  File "G:\GITHUB\Proxy\proxy_pool\utils\mongo_pool.py", line 52, in find_sort
    proxies = self.proxies.find(filter=conditions, limit=count).sort(
  File "C:\Users\admin\AppData\Local\Programs\Python\Python37\lib\site-packages\pymongo\collection.py", line 1432, in find
    return Cursor(self, *args, **kwargs)
  File "C:\Users\admin\AppData\Local\Programs\Python\Python37\lib\site-packages\pymongo\cursor.py", line 191, in __init__
    raise TypeError("limit must be an instance of int")
TypeError: limit must be an instance of int
2022-03-27 17:26:03 _internal.py [line:225] INFO:127.0.0.1 - - [27/Mar/2022 17:26:03] "[35m[1mGET /proxies HTTP/1.1[0m" 500 -
2022-03-27 18:28:39 http_validate.py [line:13] WARNING:start check proxy
2022-03-27 18:28:39 http_validate.py [line:13] WARNING:start check proxy
2022-03-27 18:28:39 http_validate.py [line:13] WARNING:start check proxy
2022-03-27 18:28:39 http_validate.py [line:13] WARNING:start check proxy
2022-03-27 18:28:39 http_validate.py [line:13] WARNING:start check proxy
2022-03-27 18:28:39 connectionpool.py [line:230] DEBUG:Starting new HTTP connection (1): 58.152.94.212:8080
2022-03-27 18:28:39 connectionpool.py [line:230] DEBUG:Starting new HTTP connection (1): 119.190.89.51:9000
2022-03-27 18:28:39 connectionpool.py [line:230] DEBUG:Starting new HTTP connection (1): 27.208.139.163:8060
2022-03-27 18:28:39 connectionpool.py [line:230] DEBUG:Starting new HTTP connection (1): 103.140.126.61:8888
2022-03-27 18:28:39 connectionpool.py [line:230] DEBUG:Starting new HTTP connection (1): 103.146.30.125:8080
2022-03-27 18:28:41 connectionpool.py [line:442] DEBUG:http://58.152.94.212:8080 "GET http://httpbin.org/get HTTP/1.1" 200 393
2022-03-27 18:28:41 http_validate.py [line:13] WARNING:start check proxy
2022-03-27 18:28:41 connectionpool.py [line:941] DEBUG:Starting new HTTPS connection (1): httpbin.org:443
2022-03-27 18:28:41 mongo_pool.py [line:40] INFO:已更新代理：{'ip': '58.152.94.212', 'port': '8080', 'protocol': 0, 'nick_type': 0, 'speed': 1.8621861934661865, 'score': 50, 'area': '高匿_香港电讯盈科有限公司', 'disable_domain': []}
2022-03-27 18:28:42 http_validate.py [line:13] WARNING:start check proxy
2022-03-27 18:28:42 connectionpool.py [line:941] DEBUG:Starting new HTTPS connection (1): httpbin.org:443
2022-03-27 18:28:42 http_validate.py [line:13] WARNING:start check proxy
2022-03-27 18:28:42 http_validate.py [line:13] WARNING:start check proxy
2022-03-27 18:28:42 http_validate.py [line:13] WARNING:start check proxy
2022-03-27 18:28:42 connectionpool.py [line:941] DEBUG:Starting new HTTPS connection (1): httpbin.org:443
2022-03-27 18:28:42 connectionpool.py [line:941] DEBUG:Starting new HTTPS connection (1): httpbin.org:443
2022-03-27 18:28:42 connectionpool.py [line:941] DEBUG:Starting new HTTPS connection (1): httpbin.org:443
2022-03-27 18:28:45 mongo_pool.py [line:40] INFO:已更新代理：{'ip': '119.190.89.51', 'port': '9000', 'protocol': -1, 'nick_type': -1, 'speed': -1, 'score': 49, 'area': '高匿_山东省联通', 'disable_domain': []}
2022-03-27 18:28:45 mongo_pool.py [line:40] INFO:已更新代理：{'ip': '119.190.89.51', 'port': '9000', 'protocol': -1, 'nick_type': -1, 'speed': -1, 'score': 50, 'area': '高匿_山东省联通', 'disable_domain': []}
2022-03-27 18:28:45 mongo_pool.py [line:40] INFO:已更新代理：{'ip': '103.146.30.125', 'port': '8080', 'protocol': -1, 'nick_type': -1, 'speed': -1, 'score': 49, 'area': '高匿_亚太地区', 'disable_domain': []}
2022-03-27 18:28:45 mongo_pool.py [line:40] INFO:已更新代理：{'ip': '27.208.139.163', 'port': '8060', 'protocol': -1, 'nick_type': -1, 'speed': -1, 'score': 49, 'area': '高匿_山东省威海市联通', 'disable_domain': []}
2022-03-27 18:28:45 mongo_pool.py [line:40] INFO:已更新代理：{'ip': '103.146.30.125', 'port': '8080', 'protocol': -1, 'nick_type': -1, 'speed': -1, 'score': 50, 'area': '高匿_亚太地区', 'disable_domain': []}
2022-03-27 18:28:45 mongo_pool.py [line:40] INFO:已更新代理：{'ip': '27.208.139.163', 'port': '8060', 'protocol': -1, 'nick_type': -1, 'speed': -1, 'score': 50, 'area': '高匿_山东省威海市联通', 'disable_domain': []}
2022-03-27 18:28:45 mongo_pool.py [line:40] INFO:已更新代理：{'ip': '103.140.126.61', 'port': '8888', 'protocol': -1, 'nick_type': -1, 'speed': -1, 'score': 49, 'area': 'SSL高匿_亚太地区', 'disable_domain': []}
2022-03-27 18:28:45 mongo_pool.py [line:40] INFO:已更新代理：{'ip': '103.140.126.61', 'port': '8888', 'protocol': -1, 'nick_type': -1, 'speed': -1, 'score': 50, 'area': 'SSL高匿_亚太地区', 'disable_domain': []}
2022-03-27 18:30:36 _internal.py [line:225] INFO: * Running on http://127.0.0.1:8888/ (Press CTRL+C to quit)
2022-03-27 18:30:41 _internal.py [line:225] INFO:127.0.0.1 - - [27/Mar/2022 18:30:41] "GET / HTTP/1.1" 200 -
2022-03-27 18:30:42 _internal.py [line:225] INFO:127.0.0.1 - - [27/Mar/2022 18:30:42] "[33mGET /favicon.ico HTTP/1.1[0m" 404 -
2022-03-27 18:30:50 _internal.py [line:225] INFO:127.0.0.1 - - [27/Mar/2022 18:30:50] "[33mGET /favicon.ico HTTP/1.1[0m" 404 -
2022-03-27 18:30:50 app.py [line:1458] ERROR:Exception on /proxies [GET]
Traceback (most recent call last):
  File "C:\Users\admin\AppData\Local\Programs\Python\Python37\lib\site-packages\flask\app.py", line 2073, in wsgi_app
    response = self.full_dispatch_request()
  File "C:\Users\admin\AppData\Local\Programs\Python\Python37\lib\site-packages\flask\app.py", line 1518, in full_dispatch_request
    rv = self.handle_user_exception(e)
  File "C:\Users\admin\AppData\Local\Programs\Python\Python37\lib\site-packages\flask\app.py", line 1516, in full_dispatch_request
    rv = self.dispatch_request()
  File "C:\Users\admin\AppData\Local\Programs\Python\Python37\lib\site-packages\flask\app.py", line 1502, in dispatch_request
    return self.ensure_sync(self.view_functions[rule.endpoint])(**req.view_args)
  File "G:/GITHUB/Proxy/proxy_pool/core/proxy_api.py", line 34, in get_proxies
    proxies = self.mongo_pool.get_proxies(protocol=protocol, nick_type=nick_type, domain=domain, count=count)
  File "G:\GITHUB\Proxy\proxy_pool\utils\mongo_pool.py", line 72, in get_proxies
    for proxy in self.find_sort(conditions=conditions, count=count):
  File "G:\GITHUB\Proxy\proxy_pool\utils\mongo_pool.py", line 52, in find_sort
    proxies = self.proxies.find(filter=conditions, limit=count).sort(
  File "C:\Users\admin\AppData\Local\Programs\Python\Python37\lib\site-packages\pymongo\collection.py", line 1432, in find
    return Cursor(self, *args, **kwargs)
  File "C:\Users\admin\AppData\Local\Programs\Python\Python37\lib\site-packages\pymongo\cursor.py", line 191, in __init__
    raise TypeError("limit must be an instance of int")
TypeError: limit must be an instance of int
2022-03-27 18:30:50 _internal.py [line:225] INFO:127.0.0.1 - - [27/Mar/2022 18:30:50] "[35m[1mGET /proxies HTTP/1.1[0m" 500 -
2022-03-27 18:32:59 _internal.py [line:225] INFO: * Running on http://127.0.0.1:8888/ (Press CTRL+C to quit)
2022-03-27 18:33:05 _internal.py [line:225] INFO:127.0.0.1 - - [27/Mar/2022 18:33:05] "GET /proxies HTTP/1.1" 200 -
2022-03-27 18:33:14 _internal.py [line:225] INFO:127.0.0.1 - - [27/Mar/2022 18:33:14] "GET /proxies HTTP/1.1" 200 -
2022-03-27 18:33:14 _internal.py [line:225] INFO:127.0.0.1 - - [27/Mar/2022 18:33:14] "GET /proxies HTTP/1.1" 200 -
2022-03-27 18:33:14 _internal.py [line:225] INFO:127.0.0.1 - - [27/Mar/2022 18:33:14] "GET /proxies HTTP/1.1" 200 -
2022-03-27 18:33:40 _internal.py [line:225] INFO:127.0.0.1 - - [27/Mar/2022 18:33:40] "[33mGET /favicon.ico HTTP/1.1[0m" 404 -
2022-03-27 18:33:40 _internal.py [line:225] INFO:127.0.0.1 - - [27/Mar/2022 18:33:40] "[33mGET /favicon.ico HTTP/1.1[0m" 404 -
2022-03-27 18:33:41 _internal.py [line:225] INFO:127.0.0.1 - - [27/Mar/2022 18:33:41] "[33mGET /favicon.ico HTTP/1.1[0m" 404 -
2022-03-27 18:33:41 _internal.py [line:225] INFO:127.0.0.1 - - [27/Mar/2022 18:33:41] "[33mGET /favicon.ico HTTP/1.1[0m" 404 -
2022-03-27 18:33:42 _internal.py [line:225] INFO:127.0.0.1 - - [27/Mar/2022 18:33:42] "GET /proxies?count=1 HTTP/1.1" 200 -
2022-03-27 18:33:51 _internal.py [line:225] INFO:127.0.0.1 - - [27/Mar/2022 18:33:51] "GET /proxies?count=1 HTTP/1.1" 200 -
2022-03-27 18:34:35 _internal.py [line:225] INFO:127.0.0.1 - - [27/Mar/2022 18:34:35] "[33mGET /favicon.ico HTTP/1.1[0m" 404 -
2022-03-27 18:34:36 _internal.py [line:225] INFO:127.0.0.1 - - [27/Mar/2022 18:34:36] "[33mGET /favicon.ico HTTP/1.1[0m" 404 -
2022-03-27 18:34:42 _internal.py [line:225] INFO:127.0.0.1 - - [27/Mar/2022 18:34:42] "[33mGET /favicon.ico HTTP/1.1[0m" 404 -
2022-03-27 18:34:43 _internal.py [line:225] INFO:127.0.0.1 - - [27/Mar/2022 18:34:43] "[33mGET /favicon.ico HTTP/1.1[0m" 404 -
2022-03-27 18:34:43 _internal.py [line:225] INFO:127.0.0.1 - - [27/Mar/2022 18:34:43] "[33mGET /favicon.ico HTTP/1.1[0m" 404 -
2022-03-27 18:34:44 _internal.py [line:225] INFO:127.0.0.1 - - [27/Mar/2022 18:34:44] "[33mGET /favicon.ico HTTP/1.1[0m" 404 -
2022-03-27 18:34:45 _internal.py [line:225] INFO:127.0.0.1 - - [27/Mar/2022 18:34:45] "[33mGET /favicon.ico HTTP/1.1[0m" 404 -
2022-03-27 18:34:45 _internal.py [line:225] INFO:127.0.0.1 - - [27/Mar/2022 18:34:45] "[33mGET /favicon.ico HTTP/1.1[0m" 404 -
2022-03-27 18:34:46 _internal.py [line:225] INFO:127.0.0.1 - - [27/Mar/2022 18:34:46] "[33mGET /favicon.ico HTTP/1.1[0m" 404 -
2022-03-27 18:34:46 _internal.py [line:225] INFO:127.0.0.1 - - [27/Mar/2022 18:34:46] "[33mGET /favicon.ico HTTP/1.1[0m" 404 -
2022-03-27 18:34:47 _internal.py [line:225] INFO:127.0.0.1 - - [27/Mar/2022 18:34:47] "[33mGET /favicon.ico HTTP/1.1[0m" 404 -
2022-03-27 18:34:48 _internal.py [line:225] INFO:127.0.0.1 - - [27/Mar/2022 18:34:48] "[33mGET /favicon.ico HTTP/1.1[0m" 404 -
2022-03-27 18:34:48 _internal.py [line:225] INFO:127.0.0.1 - - [27/Mar/2022 18:34:48] "[33mGET /favicon.ico HTTP/1.1[0m" 404 -
2022-03-27 18:34:49 _internal.py [line:225] INFO:127.0.0.1 - - [27/Mar/2022 18:34:49] "[33mGET /favicon.ico HTTP/1.1[0m" 404 -
2022-03-27 18:34:49 _internal.py [line:225] INFO:127.0.0.1 - - [27/Mar/2022 18:34:49] "[33mGET /favicon.ico HTTP/1.1[0m" 404 -
2022-03-27 18:34:50 _internal.py [line:225] INFO:127.0.0.1 - - [27/Mar/2022 18:34:50] "[33mGET /favicon.ico HTTP/1.1[0m" 404 -
2022-03-27 18:34:51 _internal.py [line:225] INFO:127.0.0.1 - - [27/Mar/2022 18:34:51] "[33mGET /favicon.ico HTTP/1.1[0m" 404 -
2022-03-27 18:34:51 _internal.py [line:225] INFO:127.0.0.1 - - [27/Mar/2022 18:34:51] "[33mGET /favicon.ico HTTP/1.1[0m" 404 -
2022-03-27 18:34:52 _internal.py [line:225] INFO:127.0.0.1 - - [27/Mar/2022 18:34:52] "[33mGET /favicon.ico HTTP/1.1[0m" 404 -
2022-03-27 18:34:53 _internal.py [line:225] INFO:127.0.0.1 - - [27/Mar/2022 18:34:53] "GET /proxies?count=1&protocol=None&%20nick_type=0&%20domain=None HTTP/1.1" 200 -
2022-03-27 18:35:06 _internal.py [line:225] INFO:127.0.0.1 - - [27/Mar/2022 18:35:06] "[33mGET /favicon.ico HTTP/1.1[0m" 404 -
2022-03-27 18:35:07 _internal.py [line:225] INFO:127.0.0.1 - - [27/Mar/2022 18:35:07] "[33mGET /favicon.ico HTTP/1.1[0m" 404 -
2022-03-27 18:35:07 _internal.py [line:225] INFO:127.0.0.1 - - [27/Mar/2022 18:35:07] "[33mGET /favicon.ico HTTP/1.1[0m" 404 -
2022-03-27 18:35:08 _internal.py [line:225] INFO:127.0.0.1 - - [27/Mar/2022 18:35:08] "[33mGET /favicon.ico HTTP/1.1[0m" 404 -
2022-03-27 18:35:09 _internal.py [line:225] INFO:127.0.0.1 - - [27/Mar/2022 18:35:09] "[33mGET /favicon.ico HTTP/1.1[0m" 404 -
2022-03-27 18:35:09 _internal.py [line:225] INFO:127.0.0.1 - - [27/Mar/2022 18:35:09] "[33mGET /favicon.ico HTTP/1.1[0m" 404 -
2022-03-27 18:35:10 _internal.py [line:225] INFO:127.0.0.1 - - [27/Mar/2022 18:35:10] "[33mGET /favicon.ico HTTP/1.1[0m" 404 -
2022-03-27 18:35:10 _internal.py [line:225] INFO:127.0.0.1 - - [27/Mar/2022 18:35:10] "[33mGET /favicon.ico HTTP/1.1[0m" 404 -
2022-03-27 18:35:11 _internal.py [line:225] INFO:127.0.0.1 - - [27/Mar/2022 18:35:11] "[33mGET /favicon.ico HTTP/1.1[0m" 404 -
2022-03-27 18:35:12 _internal.py [line:225] INFO:127.0.0.1 - - [27/Mar/2022 18:35:12] "[33mGET /favicon.ico HTTP/1.1[0m" 404 -
2022-03-27 18:35:12 _internal.py [line:225] INFO:127.0.0.1 - - [27/Mar/2022 18:35:12] "[33mGET /favicon.ico HTTP/1.1[0m" 404 -
2022-03-27 18:35:13 _internal.py [line:225] INFO:127.0.0.1 - - [27/Mar/2022 18:35:13] "[33mGET /favicon.ico HTTP/1.1[0m" 404 -
2022-03-27 18:35:13 _internal.py [line:225] INFO:127.0.0.1 - - [27/Mar/2022 18:35:13] "[33mGET /favicon.ico HTTP/1.1[0m" 404 -
2022-03-27 18:35:14 _internal.py [line:225] INFO:127.0.0.1 - - [27/Mar/2022 18:35:14] "GET /proxies?count=1&protocol=None&nick_type=0&domain=None HTTP/1.1" 200 -
2022-03-27 18:35:31 _internal.py [line:225] INFO:127.0.0.1 - - [27/Mar/2022 18:35:31] "GET /proxies?count=1&protocol=None&nick_type=0&domain=None HTTP/1.1" 200 -
2022-03-27 18:36:18 _internal.py [line:225] INFO:127.0.0.1 - - [27/Mar/2022 18:36:18] "[33mGET /favicon.ico HTTP/1.1[0m" 404 -
2022-03-27 18:36:19 _internal.py [line:225] INFO:127.0.0.1 - - [27/Mar/2022 18:36:19] "[33mGET /favicon.ico HTTP/1.1[0m" 404 -
2022-03-27 18:36:20 _internal.py [line:225] INFO:127.0.0.1 - - [27/Mar/2022 18:36:20] "[33mGET /favicon.ico HTTP/1.1[0m" 404 -
2022-03-27 18:36:20 _internal.py [line:225] INFO:127.0.0.1 - - [27/Mar/2022 18:36:20] "GET /proxies?count=1&protocol=0&nick_type=0&domain=None HTTP/1.1" 200 -
2022-03-27 18:36:29 _internal.py [line:225] INFO:127.0.0.1 - - [27/Mar/2022 18:36:29] "[33mGET /favicon.ico HTTP/1.1[0m" 404 -
2022-03-27 18:36:30 _internal.py [line:225] INFO:127.0.0.1 - - [27/Mar/2022 18:36:30] "[33mGET /favicon.ico HTTP/1.1[0m" 404 -
2022-03-27 18:36:30 _internal.py [line:225] INFO:127.0.0.1 - - [27/Mar/2022 18:36:30] "[33mGET /favicon.ico HTTP/1.1[0m" 404 -
2022-03-27 18:36:31 _internal.py [line:225] INFO:127.0.0.1 - - [27/Mar/2022 18:36:31] "[33mGET /favicon.ico HTTP/1.1[0m" 404 -
2022-03-27 18:36:32 _internal.py [line:225] INFO:127.0.0.1 - - [27/Mar/2022 18:36:32] "[33mGET /favicon.ico HTTP/1.1[0m" 404 -
2022-03-27 18:36:32 _internal.py [line:225] INFO:127.0.0.1 - - [27/Mar/2022 18:36:32] "GET /proxies?count=1&protocol=0&nick_type=0&domain=None HTTP/1.1" 200 -
2022-03-27 18:36:36 _internal.py [line:225] INFO:127.0.0.1 - - [27/Mar/2022 18:36:36] "[33mGET /favicon.ico HTTP/1.1[0m" 404 -
2022-03-27 18:36:36 _internal.py [line:225] INFO:127.0.0.1 - - [27/Mar/2022 18:36:36] "GET /proxies?count=0&protocol=0&nick_type=0&domain=None HTTP/1.1" 200 -
2022-03-27 18:37:42 _internal.py [line:225] INFO:127.0.0.1 - - [27/Mar/2022 18:37:42] "GET /proxies?count=0&protocol=0&nick_type=0&domain=None HTTP/1.1" 200 -
2022-03-27 18:38:12 _internal.py [line:225] INFO:127.0.0.1 - - [27/Mar/2022 18:38:12] "[33mGET /favicon.ico HTTP/1.1[0m" 404 -
2022-03-27 18:38:13 _internal.py [line:225] INFO:127.0.0.1 - - [27/Mar/2022 18:38:13] "[33mGET /favicon.ico HTTP/1.1[0m" 404 -
2022-03-27 18:38:13 _internal.py [line:225] INFO:127.0.0.1 - - [27/Mar/2022 18:38:13] "[33mGET /favicon.ico HTTP/1.1[0m" 404 -
2022-03-27 18:38:13 _internal.py [line:225] INFO:127.0.0.1 - - [27/Mar/2022 18:38:13] "GET /proxies?count=0&protocol=None&nick_type=0&domain=None HTTP/1.1" 200 -
2022-03-27 18:38:28 _internal.py [line:225] INFO:127.0.0.1 - - [27/Mar/2022 18:38:28] "[33mGET /favicon.ico HTTP/1.1[0m" 404 -
2022-03-27 18:38:29 _internal.py [line:225] INFO:127.0.0.1 - - [27/Mar/2022 18:38:29] "[33mGET /favicon.ico HTTP/1.1[0m" 404 -
2022-03-27 18:38:29 _internal.py [line:225] INFO:127.0.0.1 - - [27/Mar/2022 18:38:29] "[33mGET /favicon.ico HTTP/1.1[0m" 404 -
2022-03-27 18:38:30 _internal.py [line:225] INFO:127.0.0.1 - - [27/Mar/2022 18:38:30] "[33mGET /favicon.ico HTTP/1.1[0m" 404 -
2022-03-27 18:38:31 _internal.py [line:225] INFO:127.0.0.1 - - [27/Mar/2022 18:38:31] "[33mGET /favicon.ico HTTP/1.1[0m" 404 -
2022-03-27 18:38:31 _internal.py [line:225] INFO:127.0.0.1 - - [27/Mar/2022 18:38:31] "[33mGET /favicon.ico HTTP/1.1[0m" 404 -
2022-03-27 18:38:32 _internal.py [line:225] INFO:127.0.0.1 - - [27/Mar/2022 18:38:32] "[33mGET /favicon.ico HTTP/1.1[0m" 404 -
2022-03-27 18:38:33 _internal.py [line:225] INFO:127.0.0.1 - - [27/Mar/2022 18:38:33] "[33mGET /favicon.ico HTTP/1.1[0m" 404 -
2022-03-27 18:38:33 _internal.py [line:225] INFO:127.0.0.1 - - [27/Mar/2022 18:38:33] "GET /proxies?count=0&protocol=%22%22&nick_type=0&domain=%22%22 HTTP/1.1" 200 -
2022-03-27 18:38:38 _internal.py [line:225] INFO:127.0.0.1 - - [27/Mar/2022 18:38:38] "[33mGET /favicon.ico HTTP/1.1[0m" 404 -
2022-03-27 18:38:39 _internal.py [line:225] INFO:127.0.0.1 - - [27/Mar/2022 18:38:39] "[33mGET /favicon.ico HTTP/1.1[0m" 404 -
2022-03-27 18:38:39 _internal.py [line:225] INFO:127.0.0.1 - - [27/Mar/2022 18:38:39] "[33mGET /favicon.ico HTTP/1.1[0m" 404 -
2022-03-27 18:38:40 _internal.py [line:225] INFO:127.0.0.1 - - [27/Mar/2022 18:38:40] "[33mGET /favicon.ico HTTP/1.1[0m" 404 -
2022-03-27 18:38:40 _internal.py [line:225] INFO:127.0.0.1 - - [27/Mar/2022 18:38:40] "[33mGET /favicon.ico HTTP/1.1[0m" 404 -
2022-03-27 18:38:41 _internal.py [line:225] INFO:127.0.0.1 - - [27/Mar/2022 18:38:41] "[33mGET /favicon.ico HTTP/1.1[0m" 404 -
2022-03-27 18:38:41 _internal.py [line:225] INFO:127.0.0.1 - - [27/Mar/2022 18:38:41] "GET /proxies?count=0&nick_type=0 HTTP/1.1" 200 -
2022-03-27 19:50:31 _internal.py [line:225] INFO: * Running on http://127.0.0.1:8888/ (Press CTRL+C to quit)
2022-03-27 19:50:38 app.py [line:1458] ERROR:Exception on /proxies [GET]
Traceback (most recent call last):
  File "C:\Users\admin\AppData\Local\Programs\Python\Python37\lib\site-packages\flask\app.py", line 2073, in wsgi_app
    response = self.full_dispatch_request()
  File "C:\Users\admin\AppData\Local\Programs\Python\Python37\lib\site-packages\flask\app.py", line 1518, in full_dispatch_request
    rv = self.handle_user_exception(e)
  File "C:\Users\admin\AppData\Local\Programs\Python\Python37\lib\site-packages\flask\app.py", line 1516, in full_dispatch_request
    rv = self.dispatch_request()
  File "C:\Users\admin\AppData\Local\Programs\Python\Python37\lib\site-packages\flask\app.py", line 1502, in dispatch_request
    return self.ensure_sync(self.view_functions[rule.endpoint])(**req.view_args)
  File "G:/GITHUB/Proxy/proxy_pool/core/proxy_api.py", line 34, in get_proxies
    proxies = self.mongo_pool.get_proxies(protocol=protocol, nick_type=nick_type, domain=domain, count=count)
  File "G:\GITHUB\Proxy\proxy_pool\utils\mongo_pool.py", line 72, in get_proxies
    for proxy in self.find_sort(conditions=conditions, count=count):
  File "G:\GITHUB\Proxy\proxy_pool\utils\mongo_pool.py", line 52, in find_sort
    proxies = self.proxies.find(filter=conditions, limit=count).sort(
  File "C:\Users\admin\AppData\Local\Programs\Python\Python37\lib\site-packages\pymongo\collection.py", line 1432, in find
    return Cursor(self, *args, **kwargs)
  File "C:\Users\admin\AppData\Local\Programs\Python\Python37\lib\site-packages\pymongo\cursor.py", line 191, in __init__
    raise TypeError("limit must be an instance of int")
TypeError: limit must be an instance of int
2022-03-27 19:50:38 _internal.py [line:225] INFO:127.0.0.1 - - [27/Mar/2022 19:50:38] "[35m[1mGET /proxies?protocol=http HTTP/1.1[0m" 500 -
2022-03-27 19:51:02 app.py [line:1458] ERROR:Exception on /proxies [GET]
Traceback (most recent call last):
  File "C:\Users\admin\AppData\Local\Programs\Python\Python37\lib\site-packages\flask\app.py", line 2073, in wsgi_app
    response = self.full_dispatch_request()
  File "C:\Users\admin\AppData\Local\Programs\Python\Python37\lib\site-packages\flask\app.py", line 1518, in full_dispatch_request
    rv = self.handle_user_exception(e)
  File "C:\Users\admin\AppData\Local\Programs\Python\Python37\lib\site-packages\flask\app.py", line 1516, in full_dispatch_request
    rv = self.dispatch_request()
  File "C:\Users\admin\AppData\Local\Programs\Python\Python37\lib\site-packages\flask\app.py", line 1502, in dispatch_request
    return self.ensure_sync(self.view_functions[rule.endpoint])(**req.view_args)
  File "G:/GITHUB/Proxy/proxy_pool/core/proxy_api.py", line 34, in get_proxies
    proxies = self.mongo_pool.get_proxies(protocol=protocol, nick_type=nick_type, domain=domain, count=count)
  File "G:\GITHUB\Proxy\proxy_pool\utils\mongo_pool.py", line 72, in get_proxies
    for proxy in self.find_sort(conditions=conditions, count=count):
  File "G:\GITHUB\Proxy\proxy_pool\utils\mongo_pool.py", line 52, in find_sort
    proxies = self.proxies.find(filter=conditions, limit=count).sort(
  File "C:\Users\admin\AppData\Local\Programs\Python\Python37\lib\site-packages\pymongo\collection.py", line 1432, in find
    return Cursor(self, *args, **kwargs)
  File "C:\Users\admin\AppData\Local\Programs\Python\Python37\lib\site-packages\pymongo\cursor.py", line 191, in __init__
    raise TypeError("limit must be an instance of int")
TypeError: limit must be an instance of int
2022-03-27 19:51:02 _internal.py [line:225] INFO:127.0.0.1 - - [27/Mar/2022 19:51:02] "[35m[1mGET /proxies?protocol=http&count=1 HTTP/1.1[0m" 500 -
2022-03-27 19:51:33 app.py [line:1458] ERROR:Exception on /proxies [GET]
Traceback (most recent call last):
  File "C:\Users\admin\AppData\Local\Programs\Python\Python37\lib\site-packages\flask\app.py", line 2073, in wsgi_app
    response = self.full_dispatch_request()
  File "C:\Users\admin\AppData\Local\Programs\Python\Python37\lib\site-packages\flask\app.py", line 1518, in full_dispatch_request
    rv = self.handle_user_exception(e)
  File "C:\Users\admin\AppData\Local\Programs\Python\Python37\lib\site-packages\flask\app.py", line 1516, in full_dispatch_request
    rv = self.dispatch_request()
  File "C:\Users\admin\AppData\Local\Programs\Python\Python37\lib\site-packages\flask\app.py", line 1502, in dispatch_request
    return self.ensure_sync(self.view_functions[rule.endpoint])(**req.view_args)
  File "G:/GITHUB/Proxy/proxy_pool/core/proxy_api.py", line 34, in get_proxies
    proxies = self.mongo_pool.get_proxies(protocol=protocol, nick_type=nick_type, domain=domain, count=count)
  File "G:\GITHUB\Proxy\proxy_pool\utils\mongo_pool.py", line 72, in get_proxies
    for proxy in self.find_sort(conditions=conditions, count=count):
  File "G:\GITHUB\Proxy\proxy_pool\utils\mongo_pool.py", line 52, in find_sort
    proxies = self.proxies.find(filter=conditions, limit=count).sort(
  File "C:\Users\admin\AppData\Local\Programs\Python\Python37\lib\site-packages\pymongo\collection.py", line 1432, in find
    return Cursor(self, *args, **kwargs)
  File "C:\Users\admin\AppData\Local\Programs\Python\Python37\lib\site-packages\pymongo\cursor.py", line 191, in __init__
    raise TypeError("limit must be an instance of int")
TypeError: limit must be an instance of int
2022-03-27 19:51:33 _internal.py [line:225] INFO:127.0.0.1 - - [27/Mar/2022 19:51:33] "[35m[1mGET /proxies?protocol=%22http%22&count=1 HTTP/1.1[0m" 500 -
2022-03-27 19:51:49 app.py [line:1458] ERROR:Exception on /proxies [GET]
Traceback (most recent call last):
  File "C:\Users\admin\AppData\Local\Programs\Python\Python37\lib\site-packages\flask\app.py", line 2073, in wsgi_app
    response = self.full_dispatch_request()
  File "C:\Users\admin\AppData\Local\Programs\Python\Python37\lib\site-packages\flask\app.py", line 1518, in full_dispatch_request
    rv = self.handle_user_exception(e)
  File "C:\Users\admin\AppData\Local\Programs\Python\Python37\lib\site-packages\flask\app.py", line 1516, in full_dispatch_request
    rv = self.dispatch_request()
  File "C:\Users\admin\AppData\Local\Programs\Python\Python37\lib\site-packages\flask\app.py", line 1502, in dispatch_request
    return self.ensure_sync(self.view_functions[rule.endpoint])(**req.view_args)
  File "G:/GITHUB/Proxy/proxy_pool/core/proxy_api.py", line 34, in get_proxies
    proxies = self.mongo_pool.get_proxies(protocol=protocol, nick_type=nick_type, domain=domain, count=count)
  File "G:\GITHUB\Proxy\proxy_pool\utils\mongo_pool.py", line 72, in get_proxies
    for proxy in self.find_sort(conditions=conditions, count=count):
  File "G:\GITHUB\Proxy\proxy_pool\utils\mongo_pool.py", line 52, in find_sort
    proxies = self.proxies.find(filter=conditions, limit=count).sort(
  File "C:\Users\admin\AppData\Local\Programs\Python\Python37\lib\site-packages\pymongo\collection.py", line 1432, in find
    return Cursor(self, *args, **kwargs)
  File "C:\Users\admin\AppData\Local\Programs\Python\Python37\lib\site-packages\pymongo\cursor.py", line 191, in __init__
    raise TypeError("limit must be an instance of int")
TypeError: limit must be an instance of int
2022-03-27 19:51:49 _internal.py [line:225] INFO:127.0.0.1 - - [27/Mar/2022 19:51:49] "[35m[1mGET /proxies?count=0&nick_type=0 HTTP/1.1[0m" 500 -
2022-03-27 19:51:54 app.py [line:1458] ERROR:Exception on /proxies [GET]
Traceback (most recent call last):
  File "C:\Users\admin\AppData\Local\Programs\Python\Python37\lib\site-packages\flask\app.py", line 2073, in wsgi_app
    response = self.full_dispatch_request()
  File "C:\Users\admin\AppData\Local\Programs\Python\Python37\lib\site-packages\flask\app.py", line 1518, in full_dispatch_request
    rv = self.handle_user_exception(e)
  File "C:\Users\admin\AppData\Local\Programs\Python\Python37\lib\site-packages\flask\app.py", line 1516, in full_dispatch_request
    rv = self.dispatch_request()
  File "C:\Users\admin\AppData\Local\Programs\Python\Python37\lib\site-packages\flask\app.py", line 1502, in dispatch_request
    return self.ensure_sync(self.view_functions[rule.endpoint])(**req.view_args)
  File "G:/GITHUB/Proxy/proxy_pool/core/proxy_api.py", line 34, in get_proxies
    proxies = self.mongo_pool.get_proxies(protocol=protocol, nick_type=nick_type, domain=domain, count=count)
  File "G:\GITHUB\Proxy\proxy_pool\utils\mongo_pool.py", line 72, in get_proxies
    for proxy in self.find_sort(conditions=conditions, count=count):
  File "G:\GITHUB\Proxy\proxy_pool\utils\mongo_pool.py", line 52, in find_sort
    proxies = self.proxies.find(filter=conditions, limit=count).sort(
  File "C:\Users\admin\AppData\Local\Programs\Python\Python37\lib\site-packages\pymongo\collection.py", line 1432, in find
    return Cursor(self, *args, **kwargs)
  File "C:\Users\admin\AppData\Local\Programs\Python\Python37\lib\site-packages\pymongo\cursor.py", line 191, in __init__
    raise TypeError("limit must be an instance of int")
TypeError: limit must be an instance of int
2022-03-27 19:51:54 _internal.py [line:225] INFO:127.0.0.1 - - [27/Mar/2022 19:51:54] "[35m[1mGET /proxies?count=0&nick_type=0 HTTP/1.1[0m" 500 -
2022-03-27 19:52:00 _internal.py [line:225] INFO:127.0.0.1 - - [27/Mar/2022 19:52:00] "[33mGET /favicon.ico HTTP/1.1[0m" 404 -
2022-03-27 19:52:01 _internal.py [line:225] INFO:127.0.0.1 - - [27/Mar/2022 19:52:01] "[33mGET /favicon.ico HTTP/1.1[0m" 404 -
2022-03-27 19:52:01 _internal.py [line:225] INFO:127.0.0.1 - - [27/Mar/2022 19:52:01] "[33mGET /favicon.ico HTTP/1.1[0m" 404 -
2022-03-27 19:52:02 _internal.py [line:225] INFO:127.0.0.1 - - [27/Mar/2022 19:52:02] "[33mGET /favicon.ico HTTP/1.1[0m" 404 -
2022-03-27 19:52:02 _internal.py [line:225] INFO:127.0.0.1 - - [27/Mar/2022 19:52:02] "[33mGET /favicon.ico HTTP/1.1[0m" 404 -
2022-03-27 19:52:03 _internal.py [line:225] INFO:127.0.0.1 - - [27/Mar/2022 19:52:03] "[33mGET /favicon.ico HTTP/1.1[0m" 404 -
2022-03-27 19:52:04 _internal.py [line:225] INFO:127.0.0.1 - - [27/Mar/2022 19:52:04] "[33mGET /favicon.ico HTTP/1.1[0m" 404 -
2022-03-27 19:52:04 _internal.py [line:225] INFO:127.0.0.1 - - [27/Mar/2022 19:52:04] "[33mGET /favicon.ico HTTP/1.1[0m" 404 -
2022-03-27 19:52:05 _internal.py [line:225] INFO:127.0.0.1 - - [27/Mar/2022 19:52:05] "[33mGET /favicon.ico HTTP/1.1[0m" 404 -
2022-03-27 19:52:05 _internal.py [line:225] INFO:127.0.0.1 - - [27/Mar/2022 19:52:05] "[33mGET /favicon.ico HTTP/1.1[0m" 404 -
2022-03-27 19:52:06 _internal.py [line:225] INFO:127.0.0.1 - - [27/Mar/2022 19:52:06] "[33mGET /favicon.ico HTTP/1.1[0m" 404 -
2022-03-27 19:52:07 _internal.py [line:225] INFO:127.0.0.1 - - [27/Mar/2022 19:52:07] "[33mGET /favicon.ico HTTP/1.1[0m" 404 -
2022-03-27 19:52:07 _internal.py [line:225] INFO:127.0.0.1 - - [27/Mar/2022 19:52:07] "[33mGET /favicon.ico HTTP/1.1[0m" 404 -
2022-03-27 19:52:08 _internal.py [line:225] INFO:127.0.0.1 - - [27/Mar/2022 19:52:08] "[33mGET /favicon.ico HTTP/1.1[0m" 404 -
2022-03-27 19:52:08 _internal.py [line:225] INFO:127.0.0.1 - - [27/Mar/2022 19:52:08] "[33mGET /favicon.ico HTTP/1.1[0m" 404 -
2022-03-27 19:52:09 _internal.py [line:225] INFO:127.0.0.1 - - [27/Mar/2022 19:52:09] "[33mGET /favicon.ico HTTP/1.1[0m" 404 -
2022-03-27 19:52:09 app.py [line:1458] ERROR:Exception on /proxies [GET]
Traceback (most recent call last):
  File "C:\Users\admin\AppData\Local\Programs\Python\Python37\lib\site-packages\flask\app.py", line 2073, in wsgi_app
    response = self.full_dispatch_request()
  File "C:\Users\admin\AppData\Local\Programs\Python\Python37\lib\site-packages\flask\app.py", line 1518, in full_dispatch_request
    rv = self.handle_user_exception(e)
  File "C:\Users\admin\AppData\Local\Programs\Python\Python37\lib\site-packages\flask\app.py", line 1516, in full_dispatch_request
    rv = self.dispatch_request()
  File "C:\Users\admin\AppData\Local\Programs\Python\Python37\lib\site-packages\flask\app.py", line 1502, in dispatch_request
    return self.ensure_sync(self.view_functions[rule.endpoint])(**req.view_args)
  File "G:/GITHUB/Proxy/proxy_pool/core/proxy_api.py", line 34, in get_proxies
    proxies = self.mongo_pool.get_proxies(protocol=protocol, nick_type=nick_type, domain=domain, count=count)
  File "G:\GITHUB\Proxy\proxy_pool\utils\mongo_pool.py", line 72, in get_proxies
    for proxy in self.find_sort(conditions=conditions, count=count):
  File "G:\GITHUB\Proxy\proxy_pool\utils\mongo_pool.py", line 52, in find_sort
    proxies = self.proxies.find(filter=conditions, limit=count).sort(
  File "C:\Users\admin\AppData\Local\Programs\Python\Python37\lib\site-packages\pymongo\collection.py", line 1432, in find
    return Cursor(self, *args, **kwargs)
  File "C:\Users\admin\AppData\Local\Programs\Python\Python37\lib\site-packages\pymongo\cursor.py", line 191, in __init__
    raise TypeError("limit must be an instance of int")
TypeError: limit must be an instance of int
2022-03-27 19:52:09 _internal.py [line:225] INFO:127.0.0.1 - - [27/Mar/2022 19:52:09] "[35m[1mGET /proxies?count=0&nick_type=0&protocol=%27HTTP%27 HTTP/1.1[0m" 500 -
2022-03-27 19:52:44 app.py [line:1458] ERROR:Exception on /proxies [GET]
Traceback (most recent call last):
  File "C:\Users\admin\AppData\Local\Programs\Python\Python37\lib\site-packages\flask\app.py", line 2073, in wsgi_app
    response = self.full_dispatch_request()
  File "C:\Users\admin\AppData\Local\Programs\Python\Python37\lib\site-packages\flask\app.py", line 1518, in full_dispatch_request
    rv = self.handle_user_exception(e)
  File "C:\Users\admin\AppData\Local\Programs\Python\Python37\lib\site-packages\flask\app.py", line 1516, in full_dispatch_request
    rv = self.dispatch_request()
  File "C:\Users\admin\AppData\Local\Programs\Python\Python37\lib\site-packages\flask\app.py", line 1502, in dispatch_request
    return self.ensure_sync(self.view_functions[rule.endpoint])(**req.view_args)
  File "G:/GITHUB/Proxy/proxy_pool/core/proxy_api.py", line 34, in get_proxies
    proxies = self.mongo_pool.get_proxies(protocol=protocol, nick_type=nick_type, domain=domain, count=count)
  File "G:\GITHUB\Proxy\proxy_pool\utils\mongo_pool.py", line 72, in get_proxies
    for proxy in self.find_sort(conditions=conditions, count=count):
  File "G:\GITHUB\Proxy\proxy_pool\utils\mongo_pool.py", line 52, in find_sort
    proxies = self.proxies.find(filter=conditions, limit=count).sort(
  File "C:\Users\admin\AppData\Local\Programs\Python\Python37\lib\site-packages\pymongo\collection.py", line 1432, in find
    return Cursor(self, *args, **kwargs)
  File "C:\Users\admin\AppData\Local\Programs\Python\Python37\lib\site-packages\pymongo\cursor.py", line 191, in __init__
    raise TypeError("limit must be an instance of int")
TypeError: limit must be an instance of int
2022-03-27 19:52:44 _internal.py [line:225] INFO:127.0.0.1 - - [27/Mar/2022 19:52:44] "[35m[1mGET /proxies?count=0&nick_type=0&protocol=%27HTTP%27 HTTP/1.1[0m" 500 -
2022-03-27 19:52:55 _internal.py [line:225] INFO:127.0.0.1 - - [27/Mar/2022 19:52:55] "[33mGET /favicon.ico HTTP/1.1[0m" 404 -
2022-03-27 19:52:56 _internal.py [line:225] INFO:127.0.0.1 - - [27/Mar/2022 19:52:56] "[33mGET /favicon.ico HTTP/1.1[0m" 404 -
2022-03-27 19:52:56 _internal.py [line:225] INFO:127.0.0.1 - - [27/Mar/2022 19:52:56] "[33mGET /favicon.ico HTTP/1.1[0m" 404 -
2022-03-27 19:52:57 app.py [line:1458] ERROR:Exception on /proxies [GET]
Traceback (most recent call last):
  File "C:\Users\admin\AppData\Local\Programs\Python\Python37\lib\site-packages\flask\app.py", line 2073, in wsgi_app
    response = self.full_dispatch_request()
  File "C:\Users\admin\AppData\Local\Programs\Python\Python37\lib\site-packages\flask\app.py", line 1518, in full_dispatch_request
    rv = self.handle_user_exception(e)
  File "C:\Users\admin\AppData\Local\Programs\Python\Python37\lib\site-packages\flask\app.py", line 1516, in full_dispatch_request
    rv = self.dispatch_request()
  File "C:\Users\admin\AppData\Local\Programs\Python\Python37\lib\site-packages\flask\app.py", line 1502, in dispatch_request
    return self.ensure_sync(self.view_functions[rule.endpoint])(**req.view_args)
  File "G:/GITHUB/Proxy/proxy_pool/core/proxy_api.py", line 34, in get_proxies
    proxies = self.mongo_pool.get_proxies(protocol=protocol, nick_type=nick_type, domain=domain, count=count)
  File "G:\GITHUB\Proxy\proxy_pool\utils\mongo_pool.py", line 72, in get_proxies
    for proxy in self.find_sort(conditions=conditions, count=count):
  File "G:\GITHUB\Proxy\proxy_pool\utils\mongo_pool.py", line 52, in find_sort
    proxies = self.proxies.find(filter=conditions, limit=count).sort(
  File "C:\Users\admin\AppData\Local\Programs\Python\Python37\lib\site-packages\pymongo\collection.py", line 1432, in find
    return Cursor(self, *args, **kwargs)
  File "C:\Users\admin\AppData\Local\Programs\Python\Python37\lib\site-packages\pymongo\cursor.py", line 191, in __init__
    raise TypeError("limit must be an instance of int")
TypeError: limit must be an instance of int
2022-03-27 19:52:57 _internal.py [line:225] INFO:127.0.0.1 - - [27/Mar/2022 19:52:57] "[35m[1mGET /proxies?count=0&nick_type=0&protocol HTTP/1.1[0m" 500 -
2022-03-27 19:53:18 _internal.py [line:225] INFO:127.0.0.1 - - [27/Mar/2022 19:53:18] "[33mGET /favicon.ico HTTP/1.1[0m" 404 -
2022-03-27 19:53:19 _internal.py [line:225] INFO:127.0.0.1 - - [27/Mar/2022 19:53:19] "[33mGET /favicon.ico HTTP/1.1[0m" 404 -
2022-03-27 19:53:19 _internal.py [line:225] INFO:127.0.0.1 - - [27/Mar/2022 19:53:19] "[33mGET /favicon.ico HTTP/1.1[0m" 404 -
2022-03-27 19:53:20 _internal.py [line:225] INFO:127.0.0.1 - - [27/Mar/2022 19:53:20] "[33mGET /favicon.ico HTTP/1.1[0m" 404 -
2022-03-27 19:53:20 _internal.py [line:225] INFO:127.0.0.1 - - [27/Mar/2022 19:53:20] "[33mGET /favicon.ico HTTP/1.1[0m" 404 -
2022-03-27 19:53:21 _internal.py [line:225] INFO:127.0.0.1 - - [27/Mar/2022 19:53:21] "[33mGET /favicon.ico HTTP/1.1[0m" 404 -
2022-03-27 19:53:22 _internal.py [line:225] INFO:127.0.0.1 - - [27/Mar/2022 19:53:22] "[33mGET /favicon.ico HTTP/1.1[0m" 404 -
2022-03-27 19:53:22 _internal.py [line:225] INFO:127.0.0.1 - - [27/Mar/2022 19:53:22] "[33mGET /favicon.ico HTTP/1.1[0m" 404 -
2022-03-27 19:53:22 app.py [line:1458] ERROR:Exception on /proxies [GET]
Traceback (most recent call last):
  File "C:\Users\admin\AppData\Local\Programs\Python\Python37\lib\site-packages\flask\app.py", line 2073, in wsgi_app
    response = self.full_dispatch_request()
  File "C:\Users\admin\AppData\Local\Programs\Python\Python37\lib\site-packages\flask\app.py", line 1518, in full_dispatch_request
    rv = self.handle_user_exception(e)
  File "C:\Users\admin\AppData\Local\Programs\Python\Python37\lib\site-packages\flask\app.py", line 1516, in full_dispatch_request
    rv = self.dispatch_request()
  File "C:\Users\admin\AppData\Local\Programs\Python\Python37\lib\site-packages\flask\app.py", line 1502, in dispatch_request
    return self.ensure_sync(self.view_functions[rule.endpoint])(**req.view_args)
  File "G:/GITHUB/Proxy/proxy_pool/core/proxy_api.py", line 34, in get_proxies
    proxies = self.mongo_pool.get_proxies(protocol=protocol, nick_type=nick_type, domain=domain, count=count)
  File "G:\GITHUB\Proxy\proxy_pool\utils\mongo_pool.py", line 72, in get_proxies
    for proxy in self.find_sort(conditions=conditions, count=count):
  File "G:\GITHUB\Proxy\proxy_pool\utils\mongo_pool.py", line 52, in find_sort
    proxies = self.proxies.find(filter=conditions, limit=count).sort(
  File "C:\Users\admin\AppData\Local\Programs\Python\Python37\lib\site-packages\pymongo\collection.py", line 1432, in find
    return Cursor(self, *args, **kwargs)
  File "C:\Users\admin\AppData\Local\Programs\Python\Python37\lib\site-packages\pymongo\cursor.py", line 191, in __init__
    raise TypeError("limit must be an instance of int")
TypeError: limit must be an instance of int
2022-03-27 19:53:22 _internal.py [line:225] INFO:127.0.0.1 - - [27/Mar/2022 19:53:22] "[35m[1mGET /proxies?count=0&nick_type=0&protocol=%27123%27 HTTP/1.1[0m" 500 -
2022-03-27 19:53:25 _internal.py [line:225] INFO:127.0.0.1 - - [27/Mar/2022 19:53:25] "[33mGET /favicon.ico HTTP/1.1[0m" 404 -
2022-03-27 19:53:25 _internal.py [line:225] INFO:127.0.0.1 - - [27/Mar/2022 19:53:25] "[33mGET /favicon.ico HTTP/1.1[0m" 404 -
2022-03-27 19:53:26 app.py [line:1458] ERROR:Exception on /proxies [GET]
Traceback (most recent call last):
  File "C:\Users\admin\AppData\Local\Programs\Python\Python37\lib\site-packages\flask\app.py", line 2073, in wsgi_app
    response = self.full_dispatch_request()
  File "C:\Users\admin\AppData\Local\Programs\Python\Python37\lib\site-packages\flask\app.py", line 1518, in full_dispatch_request
    rv = self.handle_user_exception(e)
  File "C:\Users\admin\AppData\Local\Programs\Python\Python37\lib\site-packages\flask\app.py", line 1516, in full_dispatch_request
    rv = self.dispatch_request()
  File "C:\Users\admin\AppData\Local\Programs\Python\Python37\lib\site-packages\flask\app.py", line 1502, in dispatch_request
    return self.ensure_sync(self.view_functions[rule.endpoint])(**req.view_args)
  File "G:/GITHUB/Proxy/proxy_pool/core/proxy_api.py", line 34, in get_proxies
    proxies = self.mongo_pool.get_proxies(protocol=protocol, nick_type=nick_type, domain=domain, count=count)
  File "G:\GITHUB\Proxy\proxy_pool\utils\mongo_pool.py", line 72, in get_proxies
    for proxy in self.find_sort(conditions=conditions, count=count):
  File "G:\GITHUB\Proxy\proxy_pool\utils\mongo_pool.py", line 52, in find_sort
    proxies = self.proxies.find(filter=conditions, limit=count).sort(
  File "C:\Users\admin\AppData\Local\Programs\Python\Python37\lib\site-packages\pymongo\collection.py", line 1432, in find
    return Cursor(self, *args, **kwargs)
  File "C:\Users\admin\AppData\Local\Programs\Python\Python37\lib\site-packages\pymongo\cursor.py", line 191, in __init__
    raise TypeError("limit must be an instance of int")
TypeError: limit must be an instance of int
2022-03-27 19:53:26 _internal.py [line:225] INFO:127.0.0.1 - - [27/Mar/2022 19:53:26] "[35m[1mGET /proxies?count=0&nick_type=0&protocol=123 HTTP/1.1[0m" 500 -
2022-03-27 19:53:40 app.py [line:1458] ERROR:Exception on /proxies [GET]
Traceback (most recent call last):
  File "C:\Users\admin\AppData\Local\Programs\Python\Python37\lib\site-packages\flask\app.py", line 2073, in wsgi_app
    response = self.full_dispatch_request()
  File "C:\Users\admin\AppData\Local\Programs\Python\Python37\lib\site-packages\flask\app.py", line 1518, in full_dispatch_request
    rv = self.handle_user_exception(e)
  File "C:\Users\admin\AppData\Local\Programs\Python\Python37\lib\site-packages\flask\app.py", line 1516, in full_dispatch_request
    rv = self.dispatch_request()
  File "C:\Users\admin\AppData\Local\Programs\Python\Python37\lib\site-packages\flask\app.py", line 1502, in dispatch_request
    return self.ensure_sync(self.view_functions[rule.endpoint])(**req.view_args)
  File "G:/GITHUB/Proxy/proxy_pool/core/proxy_api.py", line 34, in get_proxies
    proxies = self.mongo_pool.get_proxies(protocol=protocol, nick_type=nick_type, domain=domain, count=count)
  File "G:\GITHUB\Proxy\proxy_pool\utils\mongo_pool.py", line 72, in get_proxies
    for proxy in self.find_sort(conditions=conditions, count=count):
  File "G:\GITHUB\Proxy\proxy_pool\utils\mongo_pool.py", line 52, in find_sort
    proxies = self.proxies.find(filter=conditions, limit=count).sort(
  File "C:\Users\admin\AppData\Local\Programs\Python\Python37\lib\site-packages\pymongo\collection.py", line 1432, in find
    return Cursor(self, *args, **kwargs)
  File "C:\Users\admin\AppData\Local\Programs\Python\Python37\lib\site-packages\pymongo\cursor.py", line 191, in __init__
    raise TypeError("limit must be an instance of int")
TypeError: limit must be an instance of int
2022-03-27 19:53:40 _internal.py [line:225] INFO:127.0.0.1 - - [27/Mar/2022 19:53:40] "[35m[1mGET /proxies?count=0&nick_type=0&protocol=123 HTTP/1.1[0m" 500 -
2022-03-27 19:54:57 _internal.py [line:225] INFO:127.0.0.1 - - [27/Mar/2022 19:54:57] "[33mGET /proxie?protocol=http HTTP/1.1[0m" 404 -
2022-03-27 19:55:18 _internal.py [line:225] INFO:127.0.0.1 - - [27/Mar/2022 19:55:18] "[33mGET /proxie?protocol=http&count=1 HTTP/1.1[0m" 404 -
2022-03-27 19:55:24 _internal.py [line:225] INFO:127.0.0.1 - - [27/Mar/2022 19:55:24] "[33mPOST /proxie?protocol=http&count=1 HTTP/1.1[0m" 404 -
2022-03-27 19:55:26 _internal.py [line:225] INFO:127.0.0.1 - - [27/Mar/2022 19:55:26] "[33mPOST /proxie?protocol=http&count=1 HTTP/1.1[0m" 404 -
2022-03-27 19:55:27 _internal.py [line:225] INFO:127.0.0.1 - - [27/Mar/2022 19:55:27] "[33mPOST /proxie?protocol=http&count=1 HTTP/1.1[0m" 404 -
2022-03-27 19:55:28 _internal.py [line:225] INFO:127.0.0.1 - - [27/Mar/2022 19:55:28] "[33mPOST /proxie?protocol=http&count=1 HTTP/1.1[0m" 404 -
2022-03-27 19:55:35 _internal.py [line:225] INFO:127.0.0.1 - - [27/Mar/2022 19:55:35] "[33mPOST /proxie?protocol=http&count=1 HTTP/1.1[0m" 404 -
2022-03-27 19:56:14 _internal.py [line:225] INFO: * Running on http://127.0.0.1:8888/ (Press CTRL+C to quit)
2022-03-27 19:56:17 _internal.py [line:225] INFO:127.0.0.1 - - [27/Mar/2022 19:56:17] "[33mPOST /proxie?protocol=http&count=1 HTTP/1.1[0m" 404 -
2022-03-27 19:56:24 _internal.py [line:225] INFO:127.0.0.1 - - [27/Mar/2022 19:56:24] "[33mPOST /proxie?protocol=http&count=1 HTTP/1.1[0m" 404 -
2022-03-27 19:56:52 _internal.py [line:225] INFO: * Running on http://127.0.0.1:8888/ (Press CTRL+C to quit)
2022-03-27 19:56:57 _internal.py [line:225] INFO:127.0.0.1 - - [27/Mar/2022 19:56:57] "[33mPOST /proxie?protocol=http&count=1 HTTP/1.1[0m" 404 -
2022-03-27 19:57:13 _internal.py [line:225] INFO:127.0.0.1 - - [27/Mar/2022 19:57:13] "[33mGET /proxie?protocol=http&count=1 HTTP/1.1[0m" 404 -
2022-03-27 19:57:18 _internal.py [line:225] INFO:127.0.0.1 - - [27/Mar/2022 19:57:18] "[33mGET /proxie?protocol=http&count=1 HTTP/1.1[0m" 404 -
2022-03-27 19:57:50 app.py [line:1458] ERROR:Exception on /proxies [GET]
Traceback (most recent call last):
  File "C:\Users\admin\AppData\Local\Programs\Python\Python37\lib\site-packages\flask\app.py", line 2073, in wsgi_app
    response = self.full_dispatch_request()
  File "C:\Users\admin\AppData\Local\Programs\Python\Python37\lib\site-packages\flask\app.py", line 1518, in full_dispatch_request
    rv = self.handle_user_exception(e)
  File "C:\Users\admin\AppData\Local\Programs\Python\Python37\lib\site-packages\flask\app.py", line 1516, in full_dispatch_request
    rv = self.dispatch_request()
  File "C:\Users\admin\AppData\Local\Programs\Python\Python37\lib\site-packages\flask\app.py", line 1502, in dispatch_request
    return self.ensure_sync(self.view_functions[rule.endpoint])(**req.view_args)
  File "G:/GITHUB/Proxy/proxy_pool/core/proxy_api.py", line 36, in get_proxies
    proxies = self.mongo_pool.get_proxies(protocol=protocol, nick_type=nick_type, domain=domain, count=count)
  File "G:\GITHUB\Proxy\proxy_pool\utils\mongo_pool.py", line 72, in get_proxies
    for proxy in self.find_sort(conditions=conditions, count=count):
  File "G:\GITHUB\Proxy\proxy_pool\utils\mongo_pool.py", line 52, in find_sort
    proxies = self.proxies.find(filter=conditions, limit=count).sort(
  File "C:\Users\admin\AppData\Local\Programs\Python\Python37\lib\site-packages\pymongo\collection.py", line 1432, in find
    return Cursor(self, *args, **kwargs)
  File "C:\Users\admin\AppData\Local\Programs\Python\Python37\lib\site-packages\pymongo\cursor.py", line 191, in __init__
    raise TypeError("limit must be an instance of int")
TypeError: limit must be an instance of int
2022-03-27 19:57:50 _internal.py [line:225] INFO:127.0.0.1 - - [27/Mar/2022 19:57:50] "[35m[1mGET /proxies HTTP/1.1[0m" 500 -
2022-03-27 19:58:19 app.py [line:1458] ERROR:Exception on /proxies [GET]
Traceback (most recent call last):
  File "C:\Users\admin\AppData\Local\Programs\Python\Python37\lib\site-packages\flask\app.py", line 2073, in wsgi_app
    response = self.full_dispatch_request()
  File "C:\Users\admin\AppData\Local\Programs\Python\Python37\lib\site-packages\flask\app.py", line 1518, in full_dispatch_request
    rv = self.handle_user_exception(e)
  File "C:\Users\admin\AppData\Local\Programs\Python\Python37\lib\site-packages\flask\app.py", line 1516, in full_dispatch_request
    rv = self.dispatch_request()
  File "C:\Users\admin\AppData\Local\Programs\Python\Python37\lib\site-packages\flask\app.py", line 1502, in dispatch_request
    return self.ensure_sync(self.view_functions[rule.endpoint])(**req.view_args)
  File "G:/GITHUB/Proxy/proxy_pool/core/proxy_api.py", line 36, in get_proxies
    proxies = self.mongo_pool.get_proxies(protocol=protocol, nick_type=nick_type, domain=domain, count=count)
  File "G:\GITHUB\Proxy\proxy_pool\utils\mongo_pool.py", line 72, in get_proxies
    for proxy in self.find_sort(conditions=conditions, count=count):
  File "G:\GITHUB\Proxy\proxy_pool\utils\mongo_pool.py", line 52, in find_sort
    proxies = self.proxies.find(filter=conditions, limit=count).sort(
  File "C:\Users\admin\AppData\Local\Programs\Python\Python37\lib\site-packages\pymongo\collection.py", line 1432, in find
    return Cursor(self, *args, **kwargs)
  File "C:\Users\admin\AppData\Local\Programs\Python\Python37\lib\site-packages\pymongo\cursor.py", line 191, in __init__
    raise TypeError("limit must be an instance of int")
TypeError: limit must be an instance of int
2022-03-27 19:58:19 _internal.py [line:225] INFO:127.0.0.1 - - [27/Mar/2022 19:58:19] "[35m[1mGET /proxies?protocol=http&count=1 HTTP/1.1[0m" 500 -
2022-03-27 19:58:24 app.py [line:1458] ERROR:Exception on /proxies [GET]
Traceback (most recent call last):
  File "C:\Users\admin\AppData\Local\Programs\Python\Python37\lib\site-packages\flask\app.py", line 2073, in wsgi_app
    response = self.full_dispatch_request()
  File "C:\Users\admin\AppData\Local\Programs\Python\Python37\lib\site-packages\flask\app.py", line 1518, in full_dispatch_request
    rv = self.handle_user_exception(e)
  File "C:\Users\admin\AppData\Local\Programs\Python\Python37\lib\site-packages\flask\app.py", line 1516, in full_dispatch_request
    rv = self.dispatch_request()
  File "C:\Users\admin\AppData\Local\Programs\Python\Python37\lib\site-packages\flask\app.py", line 1502, in dispatch_request
    return self.ensure_sync(self.view_functions[rule.endpoint])(**req.view_args)
  File "G:/GITHUB/Proxy/proxy_pool/core/proxy_api.py", line 36, in get_proxies
    proxies = self.mongo_pool.get_proxies(protocol=protocol, nick_type=nick_type, domain=domain, count=count)
  File "G:\GITHUB\Proxy\proxy_pool\utils\mongo_pool.py", line 72, in get_proxies
    for proxy in self.find_sort(conditions=conditions, count=count):
  File "G:\GITHUB\Proxy\proxy_pool\utils\mongo_pool.py", line 52, in find_sort
    proxies = self.proxies.find(filter=conditions, limit=count).sort(
  File "C:\Users\admin\AppData\Local\Programs\Python\Python37\lib\site-packages\pymongo\collection.py", line 1432, in find
    return Cursor(self, *args, **kwargs)
  File "C:\Users\admin\AppData\Local\Programs\Python\Python37\lib\site-packages\pymongo\cursor.py", line 191, in __init__
    raise TypeError("limit must be an instance of int")
TypeError: limit must be an instance of int
2022-03-27 19:58:24 _internal.py [line:225] INFO:127.0.0.1 - - [27/Mar/2022 19:58:24] "[35m[1mGET /proxies?protocol=http&count=1 HTTP/1.1[0m" 500 -
2022-03-27 19:58:30 app.py [line:1458] ERROR:Exception on /proxies [GET]
Traceback (most recent call last):
  File "C:\Users\admin\AppData\Local\Programs\Python\Python37\lib\site-packages\flask\app.py", line 2073, in wsgi_app
    response = self.full_dispatch_request()
  File "C:\Users\admin\AppData\Local\Programs\Python\Python37\lib\site-packages\flask\app.py", line 1518, in full_dispatch_request
    rv = self.handle_user_exception(e)
  File "C:\Users\admin\AppData\Local\Programs\Python\Python37\lib\site-packages\flask\app.py", line 1516, in full_dispatch_request
    rv = self.dispatch_request()
  File "C:\Users\admin\AppData\Local\Programs\Python\Python37\lib\site-packages\flask\app.py", line 1502, in dispatch_request
    return self.ensure_sync(self.view_functions[rule.endpoint])(**req.view_args)
  File "G:/GITHUB/Proxy/proxy_pool/core/proxy_api.py", line 36, in get_proxies
    proxies = self.mongo_pool.get_proxies(protocol=protocol, nick_type=nick_type, domain=domain, count=count)
  File "G:\GITHUB\Proxy\proxy_pool\utils\mongo_pool.py", line 72, in get_proxies
    for proxy in self.find_sort(conditions=conditions, count=count):
  File "G:\GITHUB\Proxy\proxy_pool\utils\mongo_pool.py", line 52, in find_sort
    proxies = self.proxies.find(filter=conditions, limit=count).sort(
  File "C:\Users\admin\AppData\Local\Programs\Python\Python37\lib\site-packages\pymongo\collection.py", line 1432, in find
    return Cursor(self, *args, **kwargs)
  File "C:\Users\admin\AppData\Local\Programs\Python\Python37\lib\site-packages\pymongo\cursor.py", line 191, in __init__
    raise TypeError("limit must be an instance of int")
TypeError: limit must be an instance of int
2022-03-27 19:58:30 _internal.py [line:225] INFO:127.0.0.1 - - [27/Mar/2022 19:58:30] "[35m[1mGET /proxies?protocol=https&count=1 HTTP/1.1[0m" 500 -
2022-03-27 19:58:49 app.py [line:1458] ERROR:Exception on /proxies [GET]
Traceback (most recent call last):
  File "C:\Users\admin\AppData\Local\Programs\Python\Python37\lib\site-packages\flask\app.py", line 2073, in wsgi_app
    response = self.full_dispatch_request()
  File "C:\Users\admin\AppData\Local\Programs\Python\Python37\lib\site-packages\flask\app.py", line 1518, in full_dispatch_request
    rv = self.handle_user_exception(e)
  File "C:\Users\admin\AppData\Local\Programs\Python\Python37\lib\site-packages\flask\app.py", line 1516, in full_dispatch_request
    rv = self.dispatch_request()
  File "C:\Users\admin\AppData\Local\Programs\Python\Python37\lib\site-packages\flask\app.py", line 1502, in dispatch_request
    return self.ensure_sync(self.view_functions[rule.endpoint])(**req.view_args)
  File "G:/GITHUB/Proxy/proxy_pool/core/proxy_api.py", line 36, in get_proxies
    proxies = self.mongo_pool.get_proxies(protocol=protocol, nick_type=nick_type, domain=domain, count=count)
  File "G:\GITHUB\Proxy\proxy_pool\utils\mongo_pool.py", line 72, in get_proxies
    for proxy in self.find_sort(conditions=conditions, count=count):
  File "G:\GITHUB\Proxy\proxy_pool\utils\mongo_pool.py", line 52, in find_sort
    proxies = self.proxies.find(filter=conditions, limit=count).sort(
  File "C:\Users\admin\AppData\Local\Programs\Python\Python37\lib\site-packages\pymongo\collection.py", line 1432, in find
    return Cursor(self, *args, **kwargs)
  File "C:\Users\admin\AppData\Local\Programs\Python\Python37\lib\site-packages\pymongo\cursor.py", line 191, in __init__
    raise TypeError("limit must be an instance of int")
TypeError: limit must be an instance of int
2022-03-27 19:58:49 _internal.py [line:225] INFO:127.0.0.1 - - [27/Mar/2022 19:58:49] "[35m[1mGET /proxies?protocol=https&count=1&nick_type=-1 HTTP/1.1[0m" 500 -
2022-03-27 19:59:45 app.py [line:1458] ERROR:Exception on /proxies [GET]
Traceback (most recent call last):
  File "C:\Users\admin\AppData\Local\Programs\Python\Python37\lib\site-packages\flask\app.py", line 2073, in wsgi_app
    response = self.full_dispatch_request()
  File "C:\Users\admin\AppData\Local\Programs\Python\Python37\lib\site-packages\flask\app.py", line 1518, in full_dispatch_request
    rv = self.handle_user_exception(e)
  File "C:\Users\admin\AppData\Local\Programs\Python\Python37\lib\site-packages\flask\app.py", line 1516, in full_dispatch_request
    rv = self.dispatch_request()
  File "C:\Users\admin\AppData\Local\Programs\Python\Python37\lib\site-packages\flask\app.py", line 1502, in dispatch_request
    return self.ensure_sync(self.view_functions[rule.endpoint])(**req.view_args)
  File "G:/GITHUB/Proxy/proxy_pool/core/proxy_api.py", line 36, in get_proxies
    proxies = self.mongo_pool.get_proxies(protocol=protocol, nick_type=nick_type, domain=domain, count=count)
  File "G:\GITHUB\Proxy\proxy_pool\utils\mongo_pool.py", line 72, in get_proxies
    for proxy in self.find_sort(conditions=conditions, count=count):
  File "G:\GITHUB\Proxy\proxy_pool\utils\mongo_pool.py", line 52, in find_sort
    proxies = self.proxies.find(filter=conditions, limit=count).sort(
  File "C:\Users\admin\AppData\Local\Programs\Python\Python37\lib\site-packages\pymongo\collection.py", line 1432, in find
    return Cursor(self, *args, **kwargs)
  File "C:\Users\admin\AppData\Local\Programs\Python\Python37\lib\site-packages\pymongo\cursor.py", line 191, in __init__
    raise TypeError("limit must be an instance of int")
TypeError: limit must be an instance of int
2022-03-27 19:59:45 _internal.py [line:225] INFO:127.0.0.1 - - [27/Mar/2022 19:59:45] "[35m[1mGET /proxies?protocol=https&count=1&nick_type=-1&disable_domain=None HTTP/1.1[0m" 500 -
2022-03-27 19:59:51 app.py [line:1458] ERROR:Exception on /proxies [GET]
Traceback (most recent call last):
  File "C:\Users\admin\AppData\Local\Programs\Python\Python37\lib\site-packages\flask\app.py", line 2073, in wsgi_app
    response = self.full_dispatch_request()
  File "C:\Users\admin\AppData\Local\Programs\Python\Python37\lib\site-packages\flask\app.py", line 1518, in full_dispatch_request
    rv = self.handle_user_exception(e)
  File "C:\Users\admin\AppData\Local\Programs\Python\Python37\lib\site-packages\flask\app.py", line 1516, in full_dispatch_request
    rv = self.dispatch_request()
  File "C:\Users\admin\AppData\Local\Programs\Python\Python37\lib\site-packages\flask\app.py", line 1502, in dispatch_request
    return self.ensure_sync(self.view_functions[rule.endpoint])(**req.view_args)
  File "G:/GITHUB/Proxy/proxy_pool/core/proxy_api.py", line 36, in get_proxies
    proxies = self.mongo_pool.get_proxies(protocol=protocol, nick_type=nick_type, domain=domain, count=count)
  File "G:\GITHUB\Proxy\proxy_pool\utils\mongo_pool.py", line 72, in get_proxies
    for proxy in self.find_sort(conditions=conditions, count=count):
  File "G:\GITHUB\Proxy\proxy_pool\utils\mongo_pool.py", line 52, in find_sort
    proxies = self.proxies.find(filter=conditions, limit=count).sort(
  File "C:\Users\admin\AppData\Local\Programs\Python\Python37\lib\site-packages\pymongo\collection.py", line 1432, in find
    return Cursor(self, *args, **kwargs)
  File "C:\Users\admin\AppData\Local\Programs\Python\Python37\lib\site-packages\pymongo\cursor.py", line 191, in __init__
    raise TypeError("limit must be an instance of int")
TypeError: limit must be an instance of int
2022-03-27 19:59:51 _internal.py [line:225] INFO:127.0.0.1 - - [27/Mar/2022 19:59:51] "[35m[1mGET /proxies?protocol=http&count=1&nick_type=-1&disable_domain=None HTTP/1.1[0m" 500 -
2022-03-27 19:59:53 app.py [line:1458] ERROR:Exception on /proxies [GET]
Traceback (most recent call last):
  File "C:\Users\admin\AppData\Local\Programs\Python\Python37\lib\site-packages\flask\app.py", line 2073, in wsgi_app
    response = self.full_dispatch_request()
  File "C:\Users\admin\AppData\Local\Programs\Python\Python37\lib\site-packages\flask\app.py", line 1518, in full_dispatch_request
    rv = self.handle_user_exception(e)
  File "C:\Users\admin\AppData\Local\Programs\Python\Python37\lib\site-packages\flask\app.py", line 1516, in full_dispatch_request
    rv = self.dispatch_request()
  File "C:\Users\admin\AppData\Local\Programs\Python\Python37\lib\site-packages\flask\app.py", line 1502, in dispatch_request
    return self.ensure_sync(self.view_functions[rule.endpoint])(**req.view_args)
  File "G:/GITHUB/Proxy/proxy_pool/core/proxy_api.py", line 36, in get_proxies
    proxies = self.mongo_pool.get_proxies(protocol=protocol, nick_type=nick_type, domain=domain, count=count)
  File "G:\GITHUB\Proxy\proxy_pool\utils\mongo_pool.py", line 72, in get_proxies
    for proxy in self.find_sort(conditions=conditions, count=count):
  File "G:\GITHUB\Proxy\proxy_pool\utils\mongo_pool.py", line 52, in find_sort
    proxies = self.proxies.find(filter=conditions, limit=count).sort(
  File "C:\Users\admin\AppData\Local\Programs\Python\Python37\lib\site-packages\pymongo\collection.py", line 1432, in find
    return Cursor(self, *args, **kwargs)
  File "C:\Users\admin\AppData\Local\Programs\Python\Python37\lib\site-packages\pymongo\cursor.py", line 191, in __init__
    raise TypeError("limit must be an instance of int")
TypeError: limit must be an instance of int
2022-03-27 19:59:53 _internal.py [line:225] INFO:127.0.0.1 - - [27/Mar/2022 19:59:53] "[35m[1mGET /proxies?protocol=http&count=1&nick_type=-1&disable_domain=None HTTP/1.1[0m" 500 -
2022-03-27 20:00:03 app.py [line:1458] ERROR:Exception on /proxies [GET]
Traceback (most recent call last):
  File "C:\Users\admin\AppData\Local\Programs\Python\Python37\lib\site-packages\flask\app.py", line 2073, in wsgi_app
    response = self.full_dispatch_request()
  File "C:\Users\admin\AppData\Local\Programs\Python\Python37\lib\site-packages\flask\app.py", line 1518, in full_dispatch_request
    rv = self.handle_user_exception(e)
  File "C:\Users\admin\AppData\Local\Programs\Python\Python37\lib\site-packages\flask\app.py", line 1516, in full_dispatch_request
    rv = self.dispatch_request()
  File "C:\Users\admin\AppData\Local\Programs\Python\Python37\lib\site-packages\flask\app.py", line 1502, in dispatch_request
    return self.ensure_sync(self.view_functions[rule.endpoint])(**req.view_args)
  File "G:/GITHUB/Proxy/proxy_pool/core/proxy_api.py", line 36, in get_proxies
    proxies = self.mongo_pool.get_proxies(protocol=protocol, nick_type=nick_type, domain=domain, count=count)
  File "G:\GITHUB\Proxy\proxy_pool\utils\mongo_pool.py", line 72, in get_proxies
    for proxy in self.find_sort(conditions=conditions, count=count):
  File "G:\GITHUB\Proxy\proxy_pool\utils\mongo_pool.py", line 52, in find_sort
    proxies = self.proxies.find(filter=conditions, limit=count).sort(
  File "C:\Users\admin\AppData\Local\Programs\Python\Python37\lib\site-packages\pymongo\collection.py", line 1432, in find
    return Cursor(self, *args, **kwargs)
  File "C:\Users\admin\AppData\Local\Programs\Python\Python37\lib\site-packages\pymongo\cursor.py", line 191, in __init__
    raise TypeError("limit must be an instance of int")
TypeError: limit must be an instance of int
2022-03-27 20:00:03 _internal.py [line:225] INFO:127.0.0.1 - - [27/Mar/2022 20:00:03] "[35m[1mGET /proxies?protocol=http&count=1&nick_type=-1&disable_domain=None HTTP/1.1[0m" 500 -
2022-03-27 20:00:35 app.py [line:1458] ERROR:Exception on /proxies [GET]
Traceback (most recent call last):
  File "C:\Users\admin\AppData\Local\Programs\Python\Python37\lib\site-packages\flask\app.py", line 2073, in wsgi_app
    response = self.full_dispatch_request()
  File "C:\Users\admin\AppData\Local\Programs\Python\Python37\lib\site-packages\flask\app.py", line 1518, in full_dispatch_request
    rv = self.handle_user_exception(e)
  File "C:\Users\admin\AppData\Local\Programs\Python\Python37\lib\site-packages\flask\app.py", line 1516, in full_dispatch_request
    rv = self.dispatch_request()
  File "C:\Users\admin\AppData\Local\Programs\Python\Python37\lib\site-packages\flask\app.py", line 1502, in dispatch_request
    return self.ensure_sync(self.view_functions[rule.endpoint])(**req.view_args)
  File "G:/GITHUB/Proxy/proxy_pool/core/proxy_api.py", line 36, in get_proxies
    proxies = self.mongo_pool.get_proxies(protocol=protocol, nick_type=nick_type, domain=domain, count=count)
  File "G:\GITHUB\Proxy\proxy_pool\utils\mongo_pool.py", line 72, in get_proxies
    for proxy in self.find_sort(conditions=conditions, count=count):
  File "G:\GITHUB\Proxy\proxy_pool\utils\mongo_pool.py", line 52, in find_sort
    proxies = self.proxies.find(filter=conditions, limit=count).sort(
  File "C:\Users\admin\AppData\Local\Programs\Python\Python37\lib\site-packages\pymongo\collection.py", line 1432, in find
    return Cursor(self, *args, **kwargs)
  File "C:\Users\admin\AppData\Local\Programs\Python\Python37\lib\site-packages\pymongo\cursor.py", line 191, in __init__
    raise TypeError("limit must be an instance of int")
TypeError: limit must be an instance of int
2022-03-27 20:00:35 _internal.py [line:225] INFO:127.0.0.1 - - [27/Mar/2022 20:00:35] "[35m[1mGET /proxies?protocol=http&count=1&nick_type=-1&disable_domain=-1 HTTP/1.1[0m" 500 -
2022-03-27 20:00:39 app.py [line:1458] ERROR:Exception on /proxies [GET]
Traceback (most recent call last):
  File "C:\Users\admin\AppData\Local\Programs\Python\Python37\lib\site-packages\flask\app.py", line 2073, in wsgi_app
    response = self.full_dispatch_request()
  File "C:\Users\admin\AppData\Local\Programs\Python\Python37\lib\site-packages\flask\app.py", line 1518, in full_dispatch_request
    rv = self.handle_user_exception(e)
  File "C:\Users\admin\AppData\Local\Programs\Python\Python37\lib\site-packages\flask\app.py", line 1516, in full_dispatch_request
    rv = self.dispatch_request()
  File "C:\Users\admin\AppData\Local\Programs\Python\Python37\lib\site-packages\flask\app.py", line 1502, in dispatch_request
    return self.ensure_sync(self.view_functions[rule.endpoint])(**req.view_args)
  File "G:/GITHUB/Proxy/proxy_pool/core/proxy_api.py", line 36, in get_proxies
    proxies = self.mongo_pool.get_proxies(protocol=protocol, nick_type=nick_type, domain=domain, count=count)
  File "G:\GITHUB\Proxy\proxy_pool\utils\mongo_pool.py", line 72, in get_proxies
    for proxy in self.find_sort(conditions=conditions, count=count):
  File "G:\GITHUB\Proxy\proxy_pool\utils\mongo_pool.py", line 52, in find_sort
    proxies = self.proxies.find(filter=conditions, limit=count).sort(
  File "C:\Users\admin\AppData\Local\Programs\Python\Python37\lib\site-packages\pymongo\collection.py", line 1432, in find
    return Cursor(self, *args, **kwargs)
  File "C:\Users\admin\AppData\Local\Programs\Python\Python37\lib\site-packages\pymongo\cursor.py", line 191, in __init__
    raise TypeError("limit must be an instance of int")
TypeError: limit must be an instance of int
2022-03-27 20:00:39 _internal.py [line:225] INFO:127.0.0.1 - - [27/Mar/2022 20:00:39] "[35m[1mGET /proxies?protocol=http&count=1&nick_type=-1&disable_domain=-1 HTTP/1.1[0m" 500 -
2022-03-27 20:01:46 _internal.py [line:225] INFO: * Running on http://127.0.0.1:8888/ (Press CTRL+C to quit)
2022-03-27 20:01:49 app.py [line:1458] ERROR:Exception on /proxies [GET]
Traceback (most recent call last):
  File "C:\Users\admin\AppData\Local\Programs\Python\Python37\lib\site-packages\flask\app.py", line 2073, in wsgi_app
    response = self.full_dispatch_request()
  File "C:\Users\admin\AppData\Local\Programs\Python\Python37\lib\site-packages\flask\app.py", line 1518, in full_dispatch_request
    rv = self.handle_user_exception(e)
  File "C:\Users\admin\AppData\Local\Programs\Python\Python37\lib\site-packages\flask\app.py", line 1516, in full_dispatch_request
    rv = self.dispatch_request()
  File "C:\Users\admin\AppData\Local\Programs\Python\Python37\lib\site-packages\flask\app.py", line 1502, in dispatch_request
    return self.ensure_sync(self.view_functions[rule.endpoint])(**req.view_args)
  File "G:/GITHUB/Proxy/proxy_pool/core/proxy_api.py", line 36, in get_proxies
    proxies = self.mongo_pool.get_proxies(protocol=protocol, nick_type=nick_type, domain=domain, count=count)
  File "G:\GITHUB\Proxy\proxy_pool\utils\mongo_pool.py", line 73, in get_proxies
    for proxy in self.find_sort(conditions=conditions, count=count):
  File "G:\GITHUB\Proxy\proxy_pool\utils\mongo_pool.py", line 52, in find_sort
    proxies = self.proxies.find(filter=conditions, limit=count).sort(
  File "C:\Users\admin\AppData\Local\Programs\Python\Python37\lib\site-packages\pymongo\collection.py", line 1432, in find
    return Cursor(self, *args, **kwargs)
  File "C:\Users\admin\AppData\Local\Programs\Python\Python37\lib\site-packages\pymongo\cursor.py", line 191, in __init__
    raise TypeError("limit must be an instance of int")
TypeError: limit must be an instance of int
2022-03-27 20:01:49 _internal.py [line:225] INFO:127.0.0.1 - - [27/Mar/2022 20:01:49] "[35m[1mGET /proxies?protocol=http&count=1&nick_type=-1&disable_domain=-1 HTTP/1.1[0m" 500 -
2022-03-27 20:02:27 _internal.py [line:225] INFO: * Running on http://127.0.0.1:8888/ (Press CTRL+C to quit)
2022-03-27 20:02:29 app.py [line:1458] ERROR:Exception on /proxies [GET]
Traceback (most recent call last):
  File "C:\Users\admin\AppData\Local\Programs\Python\Python37\lib\site-packages\flask\app.py", line 2073, in wsgi_app
    response = self.full_dispatch_request()
  File "C:\Users\admin\AppData\Local\Programs\Python\Python37\lib\site-packages\flask\app.py", line 1518, in full_dispatch_request
    rv = self.handle_user_exception(e)
  File "C:\Users\admin\AppData\Local\Programs\Python\Python37\lib\site-packages\flask\app.py", line 1516, in full_dispatch_request
    rv = self.dispatch_request()
  File "C:\Users\admin\AppData\Local\Programs\Python\Python37\lib\site-packages\flask\app.py", line 1502, in dispatch_request
    return self.ensure_sync(self.view_functions[rule.endpoint])(**req.view_args)
  File "G:/GITHUB/Proxy/proxy_pool/core/proxy_api.py", line 36, in get_proxies
    proxies = self.mongo_pool.get_proxies(protocol=protocol, nick_type=nick_type, domain=domain, count=count)
  File "G:\GITHUB\Proxy\proxy_pool\utils\mongo_pool.py", line 73, in get_proxies
    for proxy in self.find_sort(conditions=conditions, count=count):
  File "G:\GITHUB\Proxy\proxy_pool\utils\mongo_pool.py", line 52, in find_sort
    proxies = self.proxies.find(filter=conditions, limit=count).sort(
  File "C:\Users\admin\AppData\Local\Programs\Python\Python37\lib\site-packages\pymongo\collection.py", line 1432, in find
    return Cursor(self, *args, **kwargs)
  File "C:\Users\admin\AppData\Local\Programs\Python\Python37\lib\site-packages\pymongo\cursor.py", line 191, in __init__
    raise TypeError("limit must be an instance of int")
TypeError: limit must be an instance of int
2022-03-27 20:02:29 _internal.py [line:225] INFO:127.0.0.1 - - [27/Mar/2022 20:02:29] "[35m[1mGET /proxies?protocol=http&count=1&nick_type=-1&disable_domain=-1 HTTP/1.1[0m" 500 -
2022-03-27 20:08:51 _internal.py [line:225] INFO: * Running on http://127.0.0.1:8888/ (Press CTRL+C to quit)
2022-03-27 20:08:59 app.py [line:1458] ERROR:Exception on /proxies [GET]
Traceback (most recent call last):
  File "C:\Users\admin\AppData\Local\Programs\Python\Python37\lib\site-packages\flask\app.py", line 2073, in wsgi_app
    response = self.full_dispatch_request()
  File "C:\Users\admin\AppData\Local\Programs\Python\Python37\lib\site-packages\flask\app.py", line 1518, in full_dispatch_request
    rv = self.handle_user_exception(e)
  File "C:\Users\admin\AppData\Local\Programs\Python\Python37\lib\site-packages\flask\app.py", line 1516, in full_dispatch_request
    rv = self.dispatch_request()
  File "C:\Users\admin\AppData\Local\Programs\Python\Python37\lib\site-packages\flask\app.py", line 1502, in dispatch_request
    return self.ensure_sync(self.view_functions[rule.endpoint])(**req.view_args)
  File "G:/GITHUB/Proxy/proxy_pool/core/proxy_api.py", line 36, in get_proxies
    proxies = self.mongo_pool.get_proxies(protocol=protocol, nick_type=nick_type, domain=domain, count=count)
  File "G:\GITHUB\Proxy\proxy_pool\utils\mongo_pool.py", line 75, in get_proxies
    for proxy in self.find_sort(conditions=conditions, count=count):
  File "G:\GITHUB\Proxy\proxy_pool\utils\mongo_pool.py", line 52, in find_sort
    proxies = self.proxies.find(filter=conditions, limit=count).sort(
  File "C:\Users\admin\AppData\Local\Programs\Python\Python37\lib\site-packages\pymongo\collection.py", line 1432, in find
    return Cursor(self, *args, **kwargs)
  File "C:\Users\admin\AppData\Local\Programs\Python\Python37\lib\site-packages\pymongo\cursor.py", line 191, in __init__
    raise TypeError("limit must be an instance of int")
TypeError: limit must be an instance of int
2022-03-27 20:08:59 _internal.py [line:225] INFO:127.0.0.1 - - [27/Mar/2022 20:08:59] "[35m[1mGET /proxies?protocol=test&count=3&nick_type=-1&disable_domain=-1 HTTP/1.1[0m" 500 -
2022-03-27 20:09:04 app.py [line:1458] ERROR:Exception on /proxies [GET]
Traceback (most recent call last):
  File "C:\Users\admin\AppData\Local\Programs\Python\Python37\lib\site-packages\flask\app.py", line 2073, in wsgi_app
    response = self.full_dispatch_request()
  File "C:\Users\admin\AppData\Local\Programs\Python\Python37\lib\site-packages\flask\app.py", line 1518, in full_dispatch_request
    rv = self.handle_user_exception(e)
  File "C:\Users\admin\AppData\Local\Programs\Python\Python37\lib\site-packages\flask\app.py", line 1516, in full_dispatch_request
    rv = self.dispatch_request()
  File "C:\Users\admin\AppData\Local\Programs\Python\Python37\lib\site-packages\flask\app.py", line 1502, in dispatch_request
    return self.ensure_sync(self.view_functions[rule.endpoint])(**req.view_args)
  File "G:/GITHUB/Proxy/proxy_pool/core/proxy_api.py", line 36, in get_proxies
    proxies = self.mongo_pool.get_proxies(protocol=protocol, nick_type=nick_type, domain=domain, count=count)
  File "G:\GITHUB\Proxy\proxy_pool\utils\mongo_pool.py", line 75, in get_proxies
    for proxy in self.find_sort(conditions=conditions, count=count):
  File "G:\GITHUB\Proxy\proxy_pool\utils\mongo_pool.py", line 52, in find_sort
    proxies = self.proxies.find(filter=conditions, limit=count).sort(
  File "C:\Users\admin\AppData\Local\Programs\Python\Python37\lib\site-packages\pymongo\collection.py", line 1432, in find
    return Cursor(self, *args, **kwargs)
  File "C:\Users\admin\AppData\Local\Programs\Python\Python37\lib\site-packages\pymongo\cursor.py", line 191, in __init__
    raise TypeError("limit must be an instance of int")
TypeError: limit must be an instance of int
2022-03-27 20:09:04 _internal.py [line:225] INFO:127.0.0.1 - - [27/Mar/2022 20:09:04] "[35m[1mGET /proxies?protocol=test&count=3&nick_type=-1&disable_domain=-1 HTTP/1.1[0m" 500 -
2022-03-27 20:09:52 _internal.py [line:225] INFO: * Running on http://127.0.0.1:8888/ (Press CTRL+C to quit)
2022-03-27 20:09:56 app.py [line:1458] ERROR:Exception on /proxies [GET]
Traceback (most recent call last):
  File "C:\Users\admin\AppData\Local\Programs\Python\Python37\lib\site-packages\flask\app.py", line 2073, in wsgi_app
    response = self.full_dispatch_request()
  File "C:\Users\admin\AppData\Local\Programs\Python\Python37\lib\site-packages\flask\app.py", line 1518, in full_dispatch_request
    rv = self.handle_user_exception(e)
  File "C:\Users\admin\AppData\Local\Programs\Python\Python37\lib\site-packages\flask\app.py", line 1516, in full_dispatch_request
    rv = self.dispatch_request()
  File "C:\Users\admin\AppData\Local\Programs\Python\Python37\lib\site-packages\flask\app.py", line 1502, in dispatch_request
    return self.ensure_sync(self.view_functions[rule.endpoint])(**req.view_args)
  File "G:/GITHUB/Proxy/proxy_pool/core/proxy_api.py", line 36, in get_proxies
    proxies = self.mongo_pool.get_proxies(protocol=protocol, nick_type=nick_type, domain=domain, count=count)
  File "G:\GITHUB\Proxy\proxy_pool\utils\mongo_pool.py", line 77, in get_proxies
    for proxy in self.find_sort(conditions=conditions, count=count):
  File "G:\GITHUB\Proxy\proxy_pool\utils\mongo_pool.py", line 54, in find_sort
    proxies = self.proxies.find(filter=conditions, limit=count).sort(
  File "C:\Users\admin\AppData\Local\Programs\Python\Python37\lib\site-packages\pymongo\collection.py", line 1432, in find
    return Cursor(self, *args, **kwargs)
  File "C:\Users\admin\AppData\Local\Programs\Python\Python37\lib\site-packages\pymongo\cursor.py", line 191, in __init__
    raise TypeError("limit must be an instance of int")
TypeError: limit must be an instance of int
2022-03-27 20:09:56 _internal.py [line:225] INFO:127.0.0.1 - - [27/Mar/2022 20:09:56] "[35m[1mGET /proxies?protocol=test&count=3&nick_type=-1&disable_domain=-1 HTTP/1.1[0m" 500 -
2022-03-27 20:10:56 _internal.py [line:225] INFO: * Running on http://127.0.0.1:8888/ (Press CTRL+C to quit)
2022-03-27 20:10:59 app.py [line:1458] ERROR:Exception on /proxies [GET]
Traceback (most recent call last):
  File "C:\Users\admin\AppData\Local\Programs\Python\Python37\lib\site-packages\flask\app.py", line 2073, in wsgi_app
    response = self.full_dispatch_request()
  File "C:\Users\admin\AppData\Local\Programs\Python\Python37\lib\site-packages\flask\app.py", line 1518, in full_dispatch_request
    rv = self.handle_user_exception(e)
  File "C:\Users\admin\AppData\Local\Programs\Python\Python37\lib\site-packages\flask\app.py", line 1516, in full_dispatch_request
    rv = self.dispatch_request()
  File "C:\Users\admin\AppData\Local\Programs\Python\Python37\lib\site-packages\flask\app.py", line 1502, in dispatch_request
    return self.ensure_sync(self.view_functions[rule.endpoint])(**req.view_args)
  File "G:/GITHUB/Proxy/proxy_pool/core/proxy_api.py", line 36, in get_proxies
    proxies = self.mongo_pool.get_proxies(protocol=protocol, nick_type=nick_type, domain=domain, count=count)
  File "G:\GITHUB\Proxy\proxy_pool\utils\mongo_pool.py", line 77, in get_proxies
    for proxy in self.find_sort(conditions=conditions, count=count):
  File "G:\GITHUB\Proxy\proxy_pool\utils\mongo_pool.py", line 54, in find_sort
    proxies = self.proxies.find(filter=conditions, limit=count).sort(
  File "C:\Users\admin\AppData\Local\Programs\Python\Python37\lib\site-packages\pymongo\collection.py", line 1432, in find
    return Cursor(self, *args, **kwargs)
  File "C:\Users\admin\AppData\Local\Programs\Python\Python37\lib\site-packages\pymongo\cursor.py", line 191, in __init__
    raise TypeError("limit must be an instance of int")
TypeError: limit must be an instance of int
2022-03-27 20:10:59 _internal.py [line:225] INFO:127.0.0.1 - - [27/Mar/2022 20:10:59] "[35m[1mGET /proxies?protocol=test&count=3&nick_type=-1&disable_domain=-1 HTTP/1.1[0m" 500 -
2022-03-27 20:11:41 _internal.py [line:225] INFO: * Running on http://127.0.0.1:8888/ (Press CTRL+C to quit)
2022-03-27 20:11:43 app.py [line:1458] ERROR:Exception on /proxies [GET]
Traceback (most recent call last):
  File "C:\Users\admin\AppData\Local\Programs\Python\Python37\lib\site-packages\flask\app.py", line 2073, in wsgi_app
    response = self.full_dispatch_request()
  File "C:\Users\admin\AppData\Local\Programs\Python\Python37\lib\site-packages\flask\app.py", line 1518, in full_dispatch_request
    rv = self.handle_user_exception(e)
  File "C:\Users\admin\AppData\Local\Programs\Python\Python37\lib\site-packages\flask\app.py", line 1516, in full_dispatch_request
    rv = self.dispatch_request()
  File "C:\Users\admin\AppData\Local\Programs\Python\Python37\lib\site-packages\flask\app.py", line 1502, in dispatch_request
    return self.ensure_sync(self.view_functions[rule.endpoint])(**req.view_args)
  File "G:/GITHUB/Proxy/proxy_pool/core/proxy_api.py", line 36, in get_proxies
    proxies = self.mongo_pool.get_proxies(protocol=protocol, nick_type=nick_type, domain=domain, count=count)
  File "G:\GITHUB\Proxy\proxy_pool\utils\mongo_pool.py", line 76, in get_proxies
    for proxy in self.find_sort(conditions=conditions, count=count):
  File "G:\GITHUB\Proxy\proxy_pool\utils\mongo_pool.py", line 54, in find_sort
    proxies = self.proxies.find(filter=conditions, limit=count).sort()
  File "C:\Users\admin\AppData\Local\Programs\Python\Python37\lib\site-packages\pymongo\collection.py", line 1432, in find
    return Cursor(self, *args, **kwargs)
  File "C:\Users\admin\AppData\Local\Programs\Python\Python37\lib\site-packages\pymongo\cursor.py", line 191, in __init__
    raise TypeError("limit must be an instance of int")
TypeError: limit must be an instance of int
2022-03-27 20:11:43 _internal.py [line:225] INFO:127.0.0.1 - - [27/Mar/2022 20:11:43] "[35m[1mGET /proxies?protocol=test&count=3&nick_type=-1&disable_domain=-1 HTTP/1.1[0m" 500 -
2022-03-27 20:11:55 _internal.py [line:225] INFO: * Running on http://127.0.0.1:8888/ (Press CTRL+C to quit)
2022-03-27 20:11:57 _internal.py [line:225] INFO:127.0.0.1 - - [27/Mar/2022 20:11:57] "GET /proxies?protocol=test&count=3&nick_type=-1&disable_domain=-1 HTTP/1.1" 200 -
2022-03-27 20:12:20 _internal.py [line:225] INFO: * Running on http://127.0.0.1:8888/ (Press CTRL+C to quit)
2022-03-27 20:12:24 _internal.py [line:225] INFO:127.0.0.1 - - [27/Mar/2022 20:12:24] "GET /proxies?protocol=test&count=3&nick_type=-1&disable_domain=-1 HTTP/1.1" 200 -
2022-03-27 20:13:19 _internal.py [line:225] INFO: * Running on http://127.0.0.1:8888/ (Press CTRL+C to quit)
2022-03-27 20:13:32 _internal.py [line:225] INFO:127.0.0.1 - - [27/Mar/2022 20:13:32] "GET /proxies?protocol=test&count=3&nick_type=-1&disable_domain=-1 HTTP/1.1" 200 -
2022-03-27 20:14:45 _internal.py [line:225] INFO: * Running on http://127.0.0.1:8888/ (Press CTRL+C to quit)
2022-03-27 20:14:49 _internal.py [line:225] INFO:127.0.0.1 - - [27/Mar/2022 20:14:49] "GET /proxies?protocol=test&count=3&nick_type=-1&disable_domain=-1 HTTP/1.1" 200 -
2022-03-27 20:19:18 _internal.py [line:225] INFO: * Running on http://127.0.0.1:8888/ (Press CTRL+C to quit)
2022-03-27 20:19:20 _internal.py [line:225] INFO:127.0.0.1 - - [27/Mar/2022 20:19:20] "GET /proxies?protocol=test&count=3&nick_type=-1&disable_domain=-1 HTTP/1.1" 200 -
2022-03-27 20:19:56 _internal.py [line:225] INFO: * Running on http://127.0.0.1:8888/ (Press CTRL+C to quit)
2022-03-27 20:19:58 _internal.py [line:225] INFO:127.0.0.1 - - [27/Mar/2022 20:19:58] "GET /proxies?protocol=test&count=3&nick_type=-1&disable_domain=-1 HTTP/1.1" 200 -
2022-03-27 20:20:38 _internal.py [line:225] INFO: * Running on http://127.0.0.1:8888/ (Press CTRL+C to quit)
2022-03-27 20:20:40 _internal.py [line:225] INFO:127.0.0.1 - - [27/Mar/2022 20:20:40] "GET /proxies?protocol=test&count=3&nick_type=-1&disable_domain=-1 HTTP/1.1" 200 -
2022-03-27 20:21:16 _internal.py [line:225] INFO: * Running on http://127.0.0.1:8888/ (Press CTRL+C to quit)
2022-03-27 20:21:26 _internal.py [line:225] INFO:127.0.0.1 - - [27/Mar/2022 20:21:26] "GET /proxies?protocol=test&count=3&nick_type=-1&disable_domain=-1 HTTP/1.1" 200 -
2022-03-27 20:21:40 _internal.py [line:225] INFO: * Running on http://127.0.0.1:8888/ (Press CTRL+C to quit)
2022-03-27 20:21:41 _internal.py [line:225] INFO:127.0.0.1 - - [27/Mar/2022 20:21:41] "GET /proxies?protocol=test&count=3&nick_type=-1&disable_domain=-1 HTTP/1.1" 200 -
2022-03-27 20:22:49 _internal.py [line:225] INFO: * Running on http://127.0.0.1:8888/ (Press CTRL+C to quit)
2022-03-27 20:22:51 _internal.py [line:225] INFO:127.0.0.1 - - [27/Mar/2022 20:22:51] "GET /proxies?protocol=test&count=3&nick_type=-1&disable_domain=-1 HTTP/1.1" 200 -
2022-03-27 20:23:55 _internal.py [line:225] INFO: * Running on http://127.0.0.1:8888/ (Press CTRL+C to quit)
2022-03-27 20:23:58 _internal.py [line:225] INFO:127.0.0.1 - - [27/Mar/2022 20:23:58] "GET /proxies?protocol=test&count=3&nick_type=-1&disable_domain=-1 HTTP/1.1" 200 -
2022-03-27 20:24:20 _internal.py [line:225] INFO:127.0.0.1 - - [27/Mar/2022 20:24:20] "GET /proxies?protocol=test&count=1&nick_type=-1&disable_domain=-1 HTTP/1.1" 200 -
2022-03-27 20:25:25 _internal.py [line:225] INFO: * Running on http://127.0.0.1:8888/ (Press CTRL+C to quit)
2022-03-27 20:25:28 _internal.py [line:225] INFO:127.0.0.1 - - [27/Mar/2022 20:25:28] "GET /proxies?protocol=test&count=1&nick_type=-1&disable_domain=-1 HTTP/1.1" 200 -
2022-03-27 20:25:36 _internal.py [line:225] INFO:127.0.0.1 - - [27/Mar/2022 20:25:36] "GET /proxies?protocol=test&count=1&nick_type=-1&disable_domain=-1 HTTP/1.1" 200 -
2022-03-27 20:26:02 app.py [line:1458] ERROR:Exception on /proxies [GET]
Traceback (most recent call last):
  File "C:\Users\admin\AppData\Local\Programs\Python\Python37\lib\site-packages\flask\app.py", line 2073, in wsgi_app
    response = self.full_dispatch_request()
  File "C:\Users\admin\AppData\Local\Programs\Python\Python37\lib\site-packages\flask\app.py", line 1518, in full_dispatch_request
    rv = self.handle_user_exception(e)
  File "C:\Users\admin\AppData\Local\Programs\Python\Python37\lib\site-packages\flask\app.py", line 1516, in full_dispatch_request
    rv = self.dispatch_request()
  File "C:\Users\admin\AppData\Local\Programs\Python\Python37\lib\site-packages\flask\app.py", line 1502, in dispatch_request
    return self.ensure_sync(self.view_functions[rule.endpoint])(**req.view_args)
  File "G:/GITHUB/Proxy/proxy_pool/core/proxy_api.py", line 36, in get_proxies
    proxies = self.mongo_pool.get_proxies(protocol=protocol, nick_type=nick_type, domain=domain, count=count)
  File "G:\GITHUB\Proxy\proxy_pool\utils\mongo_pool.py", line 64, in get_proxies
    'nick_type': int(nick_type)
TypeError: int() argument must be a string, a bytes-like object or a number, not 'NoneType'
2022-03-27 20:26:02 _internal.py [line:225] INFO:127.0.0.1 - - [27/Mar/2022 20:26:02] "[35m[1mGET /proxies?protocol=%22test%22&count=1 HTTP/1.1[0m" 500 -
2022-03-27 20:26:18 _internal.py [line:225] INFO:127.0.0.1 - - [27/Mar/2022 20:26:18] "GET /proxies?protocol=%22test%22&count=1&nick_type=-1 HTTP/1.1" 200 -
2022-03-27 20:26:35 _internal.py [line:225] INFO:127.0.0.1 - - [27/Mar/2022 20:26:35] "GET /proxies?protocol=test&count=1&nick_type=-1&disable_domain=-1 HTTP/1.1" 200 -
2022-03-27 20:28:07 _internal.py [line:225] INFO: * Running on http://127.0.0.1:8888/ (Press CTRL+C to quit)
2022-03-27 20:28:09 app.py [line:1458] ERROR:Exception on /proxies [GET]
Traceback (most recent call last):
  File "C:\Users\admin\AppData\Local\Programs\Python\Python37\lib\site-packages\flask\app.py", line 2073, in wsgi_app
    response = self.full_dispatch_request()
  File "C:\Users\admin\AppData\Local\Programs\Python\Python37\lib\site-packages\flask\app.py", line 1518, in full_dispatch_request
    rv = self.handle_user_exception(e)
  File "C:\Users\admin\AppData\Local\Programs\Python\Python37\lib\site-packages\flask\app.py", line 1516, in full_dispatch_request
    rv = self.dispatch_request()
  File "C:\Users\admin\AppData\Local\Programs\Python\Python37\lib\site-packages\flask\app.py", line 1502, in dispatch_request
    return self.ensure_sync(self.view_functions[rule.endpoint])(**req.view_args)
  File "G:/GITHUB/Proxy/proxy_pool/core/proxy_api.py", line 39, in get_proxies
    return json.dumps(proxies).decode('UTF8')
AttributeError: 'str' object has no attribute 'decode'
2022-03-27 20:28:09 _internal.py [line:225] INFO:127.0.0.1 - - [27/Mar/2022 20:28:09] "[35m[1mGET /proxies?protocol=test&count=1&nick_type=-1&disable_domain=-1 HTTP/1.1[0m" 500 -
2022-03-27 20:28:11 app.py [line:1458] ERROR:Exception on /proxies [GET]
Traceback (most recent call last):
  File "C:\Users\admin\AppData\Local\Programs\Python\Python37\lib\site-packages\flask\app.py", line 2073, in wsgi_app
    response = self.full_dispatch_request()
  File "C:\Users\admin\AppData\Local\Programs\Python\Python37\lib\site-packages\flask\app.py", line 1518, in full_dispatch_request
    rv = self.handle_user_exception(e)
  File "C:\Users\admin\AppData\Local\Programs\Python\Python37\lib\site-packages\flask\app.py", line 1516, in full_dispatch_request
    rv = self.dispatch_request()
  File "C:\Users\admin\AppData\Local\Programs\Python\Python37\lib\site-packages\flask\app.py", line 1502, in dispatch_request
    return self.ensure_sync(self.view_functions[rule.endpoint])(**req.view_args)
  File "G:/GITHUB/Proxy/proxy_pool/core/proxy_api.py", line 39, in get_proxies
    return json.dumps(proxies).decode('UTF8')
AttributeError: 'str' object has no attribute 'decode'
2022-03-27 20:28:11 _internal.py [line:225] INFO:127.0.0.1 - - [27/Mar/2022 20:28:11] "[35m[1mGET /proxies?protocol=test&count=1&nick_type=-1&disable_domain=-1 HTTP/1.1[0m" 500 -
2022-03-27 20:28:12 app.py [line:1458] ERROR:Exception on /proxies [GET]
Traceback (most recent call last):
  File "C:\Users\admin\AppData\Local\Programs\Python\Python37\lib\site-packages\flask\app.py", line 2073, in wsgi_app
    response = self.full_dispatch_request()
  File "C:\Users\admin\AppData\Local\Programs\Python\Python37\lib\site-packages\flask\app.py", line 1518, in full_dispatch_request
    rv = self.handle_user_exception(e)
  File "C:\Users\admin\AppData\Local\Programs\Python\Python37\lib\site-packages\flask\app.py", line 1516, in full_dispatch_request
    rv = self.dispatch_request()
  File "C:\Users\admin\AppData\Local\Programs\Python\Python37\lib\site-packages\flask\app.py", line 1502, in dispatch_request
    return self.ensure_sync(self.view_functions[rule.endpoint])(**req.view_args)
  File "G:/GITHUB/Proxy/proxy_pool/core/proxy_api.py", line 39, in get_proxies
    return json.dumps(proxies).decode('UTF8')
AttributeError: 'str' object has no attribute 'decode'
2022-03-27 20:28:12 _internal.py [line:225] INFO:127.0.0.1 - - [27/Mar/2022 20:28:12] "[35m[1mGET /proxies?protocol=test&count=1&nick_type=-1&disable_domain=-1 HTTP/1.1[0m" 500 -
2022-03-27 20:28:24 app.py [line:1458] ERROR:Exception on /proxies [GET]
Traceback (most recent call last):
  File "C:\Users\admin\AppData\Local\Programs\Python\Python37\lib\site-packages\flask\app.py", line 2073, in wsgi_app
    response = self.full_dispatch_request()
  File "C:\Users\admin\AppData\Local\Programs\Python\Python37\lib\site-packages\flask\app.py", line 1518, in full_dispatch_request
    rv = self.handle_user_exception(e)
  File "C:\Users\admin\AppData\Local\Programs\Python\Python37\lib\site-packages\flask\app.py", line 1516, in full_dispatch_request
    rv = self.dispatch_request()
  File "C:\Users\admin\AppData\Local\Programs\Python\Python37\lib\site-packages\flask\app.py", line 1502, in dispatch_request
    return self.ensure_sync(self.view_functions[rule.endpoint])(**req.view_args)
  File "G:/GITHUB/Proxy/proxy_pool/core/proxy_api.py", line 39, in get_proxies
    return json.dumps(proxies).encode('UTF8')
AttributeError: 'str' object has no attribute 'decode'
2022-03-27 20:28:24 _internal.py [line:225] INFO:127.0.0.1 - - [27/Mar/2022 20:28:24] "[35m[1mGET /proxies?protocol=test&count=1&nick_type=-1&disable_domain=-1 HTTP/1.1[0m" 500 -
2022-03-27 20:28:29 _internal.py [line:225] INFO: * Running on http://127.0.0.1:8888/ (Press CTRL+C to quit)
2022-03-27 20:28:30 _internal.py [line:225] INFO:127.0.0.1 - - [27/Mar/2022 20:28:30] "GET /proxies?protocol=test&count=1&nick_type=-1&disable_domain=-1 HTTP/1.1" 200 -
2022-03-27 20:30:56 _internal.py [line:225] INFO: * Running on http://127.0.0.1:8888/ (Press CTRL+C to quit)
2022-03-27 20:30:59 _internal.py [line:225] INFO:127.0.0.1 - - [27/Mar/2022 20:30:59] "GET /proxies?protocol=test&count=1&nick_type=-1&disable_domain=-1 HTTP/1.1" 200 -
2022-03-27 20:31:00 _internal.py [line:225] INFO:127.0.0.1 - - [27/Mar/2022 20:31:00] "GET /proxies?protocol=test&count=1&nick_type=-1&disable_domain=-1 HTTP/1.1" 200 -
2022-03-27 20:32:31 _internal.py [line:225] INFO:127.0.0.1 - - [27/Mar/2022 20:32:31] "GET /proxies?protocol=test&count=1&nick_type=-1&disable_domain=-1 HTTP/1.1" 200 -
2022-03-27 20:34:53 _internal.py [line:225] INFO:127.0.0.1 - - [27/Mar/2022 20:34:53] "GET /proxies?protocol=test&count=1&nick_type=-1&disable_domain=-1 HTTP/1.1" 200 -
2022-03-27 20:35:00 _internal.py [line:225] INFO:127.0.0.1 - - [27/Mar/2022 20:35:00] "GET /proxies?count=0&nick_type=0&protocol=123 HTTP/1.1" 200 -
2022-03-27 20:36:48 _internal.py [line:225] INFO: * Running on http://127.0.0.1:8888/ (Press CTRL+C to quit)
2022-03-27 20:36:50 _internal.py [line:225] INFO:127.0.0.1 - - [27/Mar/2022 20:36:50] "GET /proxies?protocol=test&count=1&nick_type=-1&disable_domain=-1 HTTP/1.1" 200 -
2022-03-27 20:37:02 _internal.py [line:225] INFO: * Running on http://127.0.0.1:8888/ (Press CTRL+C to quit)
2022-03-27 20:37:04 _internal.py [line:225] INFO:127.0.0.1 - - [27/Mar/2022 20:37:04] "GET /proxies?protocol=test&count=1&nick_type=-1&disable_domain=-1 HTTP/1.1" 200 -
2022-03-27 20:37:51 _internal.py [line:225] INFO: * Running on http://127.0.0.1:8888/ (Press CTRL+C to quit)
2022-03-27 20:37:53 _internal.py [line:225] INFO:127.0.0.1 - - [27/Mar/2022 20:37:53] "GET /proxies?protocol=test&count=1&nick_type=-1&disable_domain=-1 HTTP/1.1" 200 -
2022-03-27 20:39:22 _internal.py [line:225] INFO: * Running on http://127.0.0.1:8888/ (Press CTRL+C to quit)
2022-03-27 20:39:25 _internal.py [line:225] INFO:127.0.0.1 - - [27/Mar/2022 20:39:25] "GET /proxies?protocol=test&count=1&nick_type=-1&disable_domain=-1 HTTP/1.1" 200 -
2022-03-27 20:43:03 _internal.py [line:225] INFO: * Running on http://127.0.0.1:8888/ (Press CTRL+C to quit)
2022-03-27 20:43:06 _internal.py [line:225] INFO:127.0.0.1 - - [27/Mar/2022 20:43:06] "GET /proxies?protocol=test&count=1&nick_type=-1&disable_domain=-1 HTTP/1.1" 200 -
2022-03-27 21:06:28 _internal.py [line:225] INFO:127.0.0.1 - - [27/Mar/2022 21:06:28] "GET /proxies?protocol=test&count=1&nick_type=-1&disable_domain=-1 HTTP/1.1" 200 -
2022-03-27 21:09:36 _internal.py [line:225] INFO: * Running on http://127.0.0.1:8888/ (Press CTRL+C to quit)
2022-03-27 21:09:39 app.py [line:1458] ERROR:Exception on /proxies [GET]
Traceback (most recent call last):
  File "C:\Users\admin\AppData\Local\Programs\Python\Python37\lib\site-packages\flask\app.py", line 2073, in wsgi_app
    response = self.full_dispatch_request()
  File "C:\Users\admin\AppData\Local\Programs\Python\Python37\lib\site-packages\flask\app.py", line 1518, in full_dispatch_request
    rv = self.handle_user_exception(e)
  File "C:\Users\admin\AppData\Local\Programs\Python\Python37\lib\site-packages\flask\app.py", line 1516, in full_dispatch_request
    rv = self.dispatch_request()
  File "C:\Users\admin\AppData\Local\Programs\Python\Python37\lib\site-packages\flask\app.py", line 1502, in dispatch_request
    return self.ensure_sync(self.view_functions[rule.endpoint])(**req.view_args)
  File "G:/GITHUB/Proxy/proxy_pool/core/proxy_api.py", line 43, in get_proxies
    return json.dumps(proxies, encoding="UTF-8", ensure_ascii=False)
  File "C:\Users\admin\AppData\Local\Programs\Python\Python37\lib\json\__init__.py", line 238, in dumps
    **kw).encode(obj)
TypeError: __init__() got an unexpected keyword argument 'encoding'
2022-03-27 21:09:39 _internal.py [line:225] INFO:127.0.0.1 - - [27/Mar/2022 21:09:39] "[35m[1mGET /proxies?protocol=test&count=1&nick_type=-1&disable_domain=-1 HTTP/1.1[0m" 500 -
2022-03-27 21:09:42 app.py [line:1458] ERROR:Exception on /proxies [GET]
Traceback (most recent call last):
  File "C:\Users\admin\AppData\Local\Programs\Python\Python37\lib\site-packages\flask\app.py", line 2073, in wsgi_app
    response = self.full_dispatch_request()
  File "C:\Users\admin\AppData\Local\Programs\Python\Python37\lib\site-packages\flask\app.py", line 1518, in full_dispatch_request
    rv = self.handle_user_exception(e)
  File "C:\Users\admin\AppData\Local\Programs\Python\Python37\lib\site-packages\flask\app.py", line 1516, in full_dispatch_request
    rv = self.dispatch_request()
  File "C:\Users\admin\AppData\Local\Programs\Python\Python37\lib\site-packages\flask\app.py", line 1502, in dispatch_request
    return self.ensure_sync(self.view_functions[rule.endpoint])(**req.view_args)
  File "G:/GITHUB/Proxy/proxy_pool/core/proxy_api.py", line 43, in get_proxies
    return json.dumps(proxies, encoding="UTF-8", ensure_ascii=False)
  File "C:\Users\admin\AppData\Local\Programs\Python\Python37\lib\json\__init__.py", line 238, in dumps
    **kw).encode(obj)
TypeError: __init__() got an unexpected keyword argument 'encoding'
2022-03-27 21:09:42 _internal.py [line:225] INFO:127.0.0.1 - - [27/Mar/2022 21:09:42] "[35m[1mGET /proxies?protocol=test&count=1&nick_type=-1&disable_domain=-1 HTTP/1.1[0m" 500 -
2022-03-27 21:11:54 _internal.py [line:225] INFO: * Running on http://127.0.0.1:8888/ (Press CTRL+C to quit)
2022-03-27 21:11:56 app.py [line:1458] ERROR:Exception on /proxies [GET]
Traceback (most recent call last):
  File "C:\Users\admin\AppData\Local\Programs\Python\Python37\lib\site-packages\flask\app.py", line 2073, in wsgi_app
    response = self.full_dispatch_request()
  File "C:\Users\admin\AppData\Local\Programs\Python\Python37\lib\site-packages\flask\app.py", line 1518, in full_dispatch_request
    rv = self.handle_user_exception(e)
  File "C:\Users\admin\AppData\Local\Programs\Python\Python37\lib\site-packages\flask\app.py", line 1516, in full_dispatch_request
    rv = self.dispatch_request()
  File "C:\Users\admin\AppData\Local\Programs\Python\Python37\lib\site-packages\flask\app.py", line 1502, in dispatch_request
    return self.ensure_sync(self.view_functions[rule.endpoint])(**req.view_args)
  File "G:/GITHUB/Proxy/proxy_pool/core/proxy_api.py", line 43, in get_proxies
    return json.dumps(proxies, encoding="UTF-8", ensure_ascii=False)
  File "C:\Users\admin\AppData\Local\Programs\Python\Python37\lib\json\__init__.py", line 238, in dumps
    **kw).encode(obj)
TypeError: __init__() got an unexpected keyword argument 'encoding'
2022-03-27 21:11:56 _internal.py [line:225] INFO:127.0.0.1 - - [27/Mar/2022 21:11:56] "[35m[1mGET /proxies?protocol=test&count=1&nick_type=-1&disable_domain=-1 HTTP/1.1[0m" 500 -
2022-03-27 21:13:05 _internal.py [line:225] INFO: * Running on http://127.0.0.1:8888/ (Press CTRL+C to quit)
2022-03-27 21:13:06 _internal.py [line:225] INFO:127.0.0.1 - - [27/Mar/2022 21:13:06] "GET /proxies?protocol=test&count=1&nick_type=-1&disable_domain=-1 HTTP/1.1" 200 -
2022-03-27 21:14:22 _internal.py [line:225] INFO:127.0.0.1 - - [27/Mar/2022 21:14:22] "GET /proxies?protocol=test&count=1&nick_type=-1&disable_domain=-1 HTTP/1.1" 200 -
2022-03-27 21:14:23 _internal.py [line:225] INFO:127.0.0.1 - - [27/Mar/2022 21:14:23] "GET /proxies?protocol=test&count=1&nick_type=-1&disable_domain=-1 HTTP/1.1" 200 -
2022-03-27 21:14:23 _internal.py [line:225] INFO:127.0.0.1 - - [27/Mar/2022 21:14:23] "GET /proxies?protocol=test&count=1&nick_type=-1&disable_domain=-1 HTTP/1.1" 200 -
2022-03-27 21:14:24 _internal.py [line:225] INFO:127.0.0.1 - - [27/Mar/2022 21:14:24] "GET /proxies?protocol=test&count=1&nick_type=-1&disable_domain=-1 HTTP/1.1" 200 -
2022-03-27 21:14:25 _internal.py [line:225] INFO:127.0.0.1 - - [27/Mar/2022 21:14:25] "GET /proxies?protocol=test&count=1&nick_type=-1&disable_domain=-1 HTTP/1.1" 200 -
2022-03-27 21:14:26 _internal.py [line:225] INFO:127.0.0.1 - - [27/Mar/2022 21:14:26] "GET /proxies?protocol=test&count=1&nick_type=-1&disable_domain=-1 HTTP/1.1" 200 -
2022-03-27 21:14:34 _internal.py [line:225] INFO:127.0.0.1 - - [27/Mar/2022 21:14:34] "GET /proxies?protocol=test&count=3&nick_type=-1&disable_domain=-1 HTTP/1.1" 200 -
2022-03-27 21:14:45 _internal.py [line:225] INFO:127.0.0.1 - - [27/Mar/2022 21:14:45] "GET /proxies?protocol=test&count=3&nick_type=-1&disable_domain=-1 HTTP/1.1" 200 -
2022-03-27 21:15:26 _internal.py [line:225] INFO:127.0.0.1 - - [27/Mar/2022 21:15:26] "GET /random?protocol=test&count=3&nick_type=-1&disable_domain=-1 HTTP/1.1" 200 -
2022-03-27 21:15:50 _internal.py [line:225] INFO:127.0.0.1 - - [27/Mar/2022 21:15:50] "GET /random?protocol=test&count=3&nick_type=-1&disable_domain=-1 HTTP/1.1" 200 -
2022-03-27 21:15:52 _internal.py [line:225] INFO:127.0.0.1 - - [27/Mar/2022 21:15:52] "GET /random?protocol=test&count=3&nick_type=-1&disable_domain=-1 HTTP/1.1" 200 -
2022-03-27 21:15:52 _internal.py [line:225] INFO:127.0.0.1 - - [27/Mar/2022 21:15:52] "GET /random?protocol=test&count=3&nick_type=-1&disable_domain=-1 HTTP/1.1" 200 -
2022-03-27 21:15:53 _internal.py [line:225] INFO:127.0.0.1 - - [27/Mar/2022 21:15:53] "GET /random?protocol=test&count=3&nick_type=-1&disable_domain=-1 HTTP/1.1" 200 -
2022-03-27 21:15:53 _internal.py [line:225] INFO:127.0.0.1 - - [27/Mar/2022 21:15:53] "GET /random?protocol=test&count=3&nick_type=-1&disable_domain=-1 HTTP/1.1" 200 -
2022-03-27 21:15:54 _internal.py [line:225] INFO:127.0.0.1 - - [27/Mar/2022 21:15:54] "GET /random?protocol=test&count=3&nick_type=-1&disable_domain=-1 HTTP/1.1" 200 -
2022-03-27 21:15:55 _internal.py [line:225] INFO:127.0.0.1 - - [27/Mar/2022 21:15:55] "GET /random?protocol=test&count=3&nick_type=-1&disable_domain=-1 HTTP/1.1" 200 -
2022-03-27 22:49:17 _internal.py [line:225] INFO:127.0.0.1 - - [27/Mar/2022 22:49:17] "GET /proxies?count=0&nick_type=0&protocol=123 HTTP/1.1" 200 -
2022-03-27 22:50:21 _internal.py [line:225] INFO:127.0.0.1 - - [27/Mar/2022 22:50:21] "GET /proxies?protocol=test&count=1&nick_type=-1&disable_domain=-1 HTTP/1.1" 200 -
